Workbook
Name Kind: OFFSET(SKU!$M$2,0,0,COUNTA(SKU!$M:$M)-1,1)
Name 英文_越文名_Tên_SP: OFFSET(SKU!$A$2,0,0,COUNTA(SKU!$A:$A)-1,1)
Name 运营: OFFSET(SKU!$L$2,0,0,COUNTA(SKU!$L:$L)-1,1)
Name 主播: OFFSET(SKU!$K$2,0,0,COUNTA(SKU!$K:$K)-1,1)

Sheet SKU
A1: 英文/越文名/Tên SP | B1: 中文名/Tên Tiếng Trung | C1: sku序列/Code SKU | D1: 品类/Loại sp | E1: 厂商/NXB | F1: 盒/箱 Hộp/Thùng | G1: 包/盒 Pack/Hộp | H1: 图片 Ảnh | I1: 预售时间 | K1: 主播 | L1: 运营 | M1: 品类
A2: Pokemon | B2: 《东株社》宝可梦水晶砖 | C2: 10001 | D2: Thẻ hộp/卡砖 | E2: 东株社 | F2: 50 | G2: 1 | K2: Thùy 阿锤 | L2: Hoàng 范范 | M2: Thẻ hộp/卡砖
A3: Moon Card Sailor Moon | B3: MoonCard月卡《美少女战士》第三弹 | C3: 10002 | D3: Card/卡牌 | E3: MoonCard月卡 | F3: 36 | G3: 13 | K3: Bội Anh 倍英 | L3: Huệ 氏惠 | M3: Card/卡牌
A4: DUO Kyn | B4: DUO米全新出品鬼灭之刃-柱合会议篇第二弹 | C4: 10003 | D4: Card/卡牌 | E4: DUO米 | F4: 36 | G4: 13 | K4: Thành Đạt 成达 | L4: Dũng 阿勇 | M4: Thẻ xé/撕撕乐
A5: Jujutsu vol 1 | B5: 初见花海咒术回战第一弹 | C5: 10004 | D5: Card/卡牌 | E5: 贝贝文创 | F5: 180 | G5: 1 | K5: Mimi | L5: Trà My 茶梅 | M5: Thẻ bự/色纸
A6: Gibli Wind | B6: 椿柚文创宫崎骏 被风吹散的秘密邮票第一弹 | C6: 10005 | D6: Card/邮票 | E6: 椿柚文创 | F6: 100 | G6: 1 | K6: Hà 小河 | L6: Tum 阿庄 | M6: Phiếu tem/邮票
A7: Mây và Hạ | B7: 云映文化「云之境の夏」第二弹·宫崎骏珍藏卡牌 | C7: 10006 | D7: Card/卡牌 | E7: 云映文化 | F7: 36 | G7: 13 | K7: Như 小如 | L7: Hoàng Oanh黄莹 | M7: Bagde/吧唧
A8: Kawaii Gibli | B8: kawaii宫崎骏梦幻之国 | C8: 10007 | D8: Card/卡牌 | E8: kawaii | F8: 36 | G8: 13 | K8: Vi 小薇 | L8: Linh 美玲 | M8: Lập thể/立体水晶
A9: X work Sailor Moon | B9: XWork美少女战士-璀璨之梦 | C9: 10008 | D9: Card/卡牌 | E9: XWork | F9: 36 | G9: 10 | K9: Phương 小芳 | L9: Tuyền 绚 | M9: Đồ chơi/玩具
A10: Vancard Sanrio | B10: 万画云游三丽鸥家族百变cos收藏卡 | C10: 10009 | D10: Card/卡牌 | E10: 万画云游 | F10: 24 | G10: 10 | K10: Thanh 阿青 | L10: Xuân Nhi 春妮
A11: Wamder Roaming Sakura | B11: 玩的入迷-魔卡少女樱第一弹—樱之绮遇 | C11: 10010 | D11: Card/卡牌 | E11: 玩的入迷 | F11: 36 | G11: 13 | K11: Zenex | L11: Tú Phượng 苏凤
A12: Gibli Hoa | B12: 灿卡文创宫崎骏第二弹《花涧物语》 | C12: 10011 | D12: Card/卡牌 | E12: 灿卡文创 | F12: 36 | G12: 13 | K12: Hoàng Anh黄英
A13: Attack on Titan | B13: 卡文化进击的巨人 | C13: 10012 | D13: Card/卡牌 | E13: 卡文化 | F13: 48 | G13: 30 | K13: Lệ Quyên 丽娟
A14: Kny Hoàng Card | B14: 皇卡 × 鬼灭《血月之契》篇决战无限城收藏卡 | C14: 10013 | D14: Card/卡牌 | E14: 皇卡 | F14: 36 | G14: 12 | K14: Khoa 科
A15: Tinh Mộng Gibli thẻ xé | B15: 星梦文创-Studio Ghibli宫崎骏撕撕乐系列 | C15: 10014 | D15: Thẻ xé/撕撕乐 | E15: 星梦文创 | F15: 100 | G15: 3 | K15: Trường Vũ 长宇
A16: MH Gibli | B16: 梦绘文创-宫崎骏第二弹 | C16: 10015 | D16: Card/卡牌 | E16: 梦绘文创 | F16: 36 | G16: 12 | K16: Phước 小福
A17: Quàng Thượng | B17: 思梨普文创《hey!国王陛下》集换式艺术家典藏卡 | C17: 10016 | D17: Card/卡牌 | E17: 思梨普文创 | F17: 36 | G17: 10 | K17: Tập huấn 培训
A18: Mộng cảnh Sailor Moon | B18: 梦境-美少女战士第一弹 | C18: 10017 | D18: Card/卡牌 | E18: 梦境 | F18: 36 | G18: 13 | K18: Kim Ngân 金银
A19: Sacred Sailor Moon | B19: 圣月美少女战士星尘协奏曲长卡 | C19: 10018 | D19: Card/卡牌 | E19: 聖月 | F19: 36 | G19: 13 | K19: Kỳ Duyên 琪媛
A20: Goods Power TQTP | B20: 谷子力量 x 竹烟波月亚克力透卡 | C20: 10019 | D20: Thẻ bự/色纸 | E20: 谷子力量 | F20: 150 | G20: 1 | K20: Ngọc Nhi 玉儿
A21: Sakura Card Fun | B21: 集卡社小樱 | C21: 10020 | D21: Card/卡牌 | E21: 集卡社 | F21: 36 | G21: 16 | K21: Phân phối các tiệm
A22: Shingu Conan phiếu tem | B22: 新谷动漫名侦探柯南·仲夏夜之恋邮票集 | C22: 10021 | D22: Phiếu tem/邮票 | E22: 新谷动漫 | F22: 25 | G22: 5 | K22: Thu Giang秋江
A23: Sailor Shining | B23: 【耀光·美少女战士】长卡卡砖 | C23: 10022 | D23: Thẻ hộp/卡砖 | E23: 耀光 | F23: 8 | G23: 24 | K23: Test Live
... A41: Kuka Maltese | B41: 酷卡文化-线条小狗3弹 | C41: 10040 | D41: Card/卡牌 | E41: 酷卡文化 | F41: 36 | G41: 11 | K41: Khách ngoài 外客
A42: Bearie Genshin Impact | B42: 小熊工坊「原神」A6色纸 | C42: 10041 | D42: Thẻ bự/色纸 | E42: 小熊工坊 | F42: 100 | G42: 1
A43: Butterbear vol 2 | B43: 黄油小熊系列收藏卡第二弹 小熊的观察日记 | C43: 10042 | D43: Card/卡牌 | E43: 玖人文化 | F43: 24 | G43: 16
A44: XR Sailor Moon | B44: 光恋XR-披荆斩棘-美少女战士 | C44: 10043 | D44: Card/卡牌 | E44: 光恋XR | F44: 36 | G44: 13
A45: Source University Genshin thẻ CD | B45: 源宇宙原神.空月の歌·周边CD票根邮票组合套装 | C45: 10044 | D45: Card/卡牌 | E45: 源宇宙原神 | F45: 100 | G45: 1
A46: Conan lập thể | B46: 名侦探柯南谜层交错 | C46: 10045 | D46: Lập thể/立体水晶 | F46: 50 | G46: 1
A47: Đèn Gibli DIY | B47: 夜灯 | C47: 10046 | D47: Đồ chơi/玩具 | E47: 夜灯 | F47: 48 | G47: 1
A48: Xưởng Teyvat Genshin Impact A6 | B48: 提瓦特工坊·原神水晶色纸 | C48: 10047 | D48: Thẻ bự/色纸 | E48: 提瓦特工坊 | F48: 90 | G48: 1
A49: Narasha Sailor Moon thẻ xé | B49: 奈良社《极昼漫游》美少女战士撕撕乐+异形小卡 | C49: 10048 | D49: Thẻ xé/撕撕乐 | E49: 奈良社 | F49: 100 | G49: 1
A50: Melting point | B50: 野火文创《月下悸动》 韩漫耽美撕撕乐 | C50: 10049 | D50: Thẻ xé/撕撕乐 | E50: 野火文创 | F50: 52 | G50: 3
A51: Hoàng tử bé và Alice | B51: 小王子与爱丽丝 | C51: 10050 | D51: Card/卡牌 | E51: 卡盟文创 | F51: 24 | G51: 12
A52: Nanka Sakura | B52: 南卡《魔卡少女樱》 | C52: 10051 | D52: Card/卡牌 | E52: 南卡 | F52: 36 | G52: 12
A53: Kayou Conan Vol 5 | B53: 柯南洞悉包第五弹 | C53: 10052 | D53: Card/卡牌 | E53: 卡游 | F53: 36 | G53: 18
A54: Hoa rơi chỉ vì quân | B54: 悦灵文创 《落花只为君》第三弹 | C54: 10053 | D54: Card/卡牌 | E54: 悦灵文创 | F54: 36 | G54: 12
A55: Mèo chiêu tài | B55: 太阳能招财猫 | C55: 10054 | D55: Đồ chơi/玩具 | E55: 招财猫 | F55: 240 | G55: 1
A56: Scroll Painting Thanh gươm diệt quỷ | B56: 绘卷文创 - 梦境入画【鬼灭之刃系列收藏卡砖】 | C56: 10055 | D56: Thẻ hộp/卡砖 | E56: 绘卷文创 | F56: 36 | G56: 5
A57: Card Fun Thiên quan tứ phúc bản hoạt hình | B57: 集卡社天官赐福动画周年纪念版 | C57: 10056 | D57: Card/卡牌 | E57: 集卡社 | F57: 48 | G57: 10
...

Sheet Nhập入库
A1: sku序列 SKU CODE | B1: 中文名 Tên tiếng Trung | C1: 英文/越文名 Tên tiếng Việt | D1: 品类 Loại sp | E1: 厂商 NXB | F1: 规格 Thông số | J1: 仓库名 Tên kho | K1: 入库人 Người nhập kho | L1: 入库时间 Thời gian | M1: 剩余库存/盒 Tồn kho (hộp) | N1: 剩余库存/包 Tồn kho (Pack)
F2: 箱 Thùng | G2: 盒/箱 Hộp | H2: 包/盒 Pack | I2: 总包数 Tổng pack
A3: =VLOOKUP($C3,SKU!$A:$I,3,FALSE) -> 10001 | B3: =VLOOKUP($C3,SKU!$A:$I,2,FALSE) -> 《东株社》宝可梦水晶砖 | C3: Pokemon | D3: =VLOOKUP($C3,SKU!$A:$I,4,FALSE) -> Thẻ hộp/卡砖 | E3: =VLOOKUP($C3,SKU!$A:$I,5,FALSE) -> 东株社 | F3: 1 | G3: =VLOOKUP($C3,SKU!$A:$I,6,FALSE) -> 50 | H3: =VLOOKUP($C3,SKU!$A:$I,7,FALSE) -> 1 | I3: =F3*G3*H3 -> 50 | J3: G层仓库 | K3: Hoàng 范范 | L3: 2025.10.15 | M3: =N3/H3 -> 0 | N3: {=SUMPRODUCT(($A$3:$A$997=A3)*($I$3:$I$997))-SUMPRODUCT((Xuất出库!$A$2:$A$986=A3)*(Xuất出库!$E$2:$E$986))-SUMPRODUCT((Xuất出库!$A$2:$A$986=A3)*(Xuất出库!$F$2:$F$986))+SUMPRODUCT((Hoàn回库!$A$2:$A$996=A3)*(Hoàn回库!$E$2:$E$996))+SUMPRODUCT((Hoàn回库!$A$2:$A$996=A3)*(Hoàn回库!$F$2:$F$996))} -> 0
A4: =VLOOKUP($C4,SKU!$A:$I,3,FALSE) -> 10002 | B4: =VLOOKUP($C4,SKU!$A:$I,2,FALSE) -> MoonCard月卡《美少女战士》第三弹 | C4: Moon Card Sailor Moon | D4: =VLOOKUP($C4,SKU!$A:$I,4,FALSE) -> Card/卡牌 | E4: =VLOOKUP($C4,SKU!$A:$I,5,FALSE) -> MoonCard月卡 | F4: 1 | G4: =VLOOKUP($C4,SKU!$A:$I,6,FALSE) -> 36 | H4: =VLOOKUP($C4,SKU!$A:$I,7,FALSE) -> 13 | I4: =F4*G4*H4 -> 468 | J4: G层仓库 | K4: Hoàng 范范 | L4: 2025.10.15 | M4: =N4/H4 -> 0 | N4: {=SUMPRODUCT(($A$3:$A$997=A4)*($I$3:$I$997))-SUMPRODUCT((Xuất出库!$A$2:$A$986=A4)*(Xuất出库!$E$2:$E$986))-SUMPRODUCT((Xuất出库!$A$2:$A$986=A4)*(Xuất出库!$F$2:$F$986))+SUMPRODUCT((Hoàn回库!$A$2:$A$996=A4)*(Hoàn回库!$E$2:$E$996))+SUMPRODUCT((Hoàn回库!$A$2:$A$996=A4)*(Hoàn回库!$F$2:$F$996))} -> 0
A5: =VLOOKUP($C5,SKU!$A:$I,3,FALSE) -> 10003 | B5: =VLOOKUP($C5,SKU!$A:$I,2,FALSE) -> DUO米全新出品鬼灭之刃-柱合会议篇第二弹 | C5: DUO Kyn | D5: =VLOOKUP($C5,SKU!$A:$I,4,FALSE) -> Card/卡牌 | E5: =VLOOKUP($C5,SKU!$A:$I,5,FALSE) -> DUO米 | F5: 2 | G5: =VLOOKUP($C5,SKU!$A:$I,6,FALSE) -> 36 | H5: =VLOOKUP($C5,SKU!$A:$I,7,FALSE) -> 13 | I5: =F5*G5*H5 -> 936 | J5: G层仓库 | K5: Hoàng 范范 | L5: 2025.10.15 | M5: =N5/H5 -> 0 | N5: {=SUMPRODUCT(($A$3:$A$997=A5)*($I$3:$I$997))-SUMPRODUCT((Xuất出库!$A$2:$A$986=A5)*(Xuất出库!$E$2:$E$986))-SUMPRODUCT((Xuất出库!$A$2:$A$986=A5)*(Xuất出库!$F$2:$F$986))+SUMPRODUCT((Hoàn回库!$A$2:$A$996=A5)*(Hoàn回库!$E$2:$E$996))+SUMPRODUCT((Hoàn回库!$A$2:$A$996=A5)*(Hoàn回库!$F$2:$F$996))} -> 0
A6: =VLOOKUP($C6,SKU!$A:$I,3,FALSE) -> 10004 | B6: =VLOOKUP($C6,SKU!$A:$I,2,FALSE) -> 初见花海咒术回战第一弹 | C6: Jujutsu vol 1 | D6: =VLOOKUP($C6,SKU!$A:$I,4,FALSE) -> Card/卡牌 | E6: =VLOOKUP($C6,SKU!$A:$I,5,FALSE) -> 贝贝文创 | F6: 1 | G6: =VLOOKUP($C6,SKU!$A:$I,6,FALSE) -> 180 | H6: =VLOOKUP($C6,SKU!$A:$I,7,FALSE) -> 1 | I6: =F6*G6*H6 -> 180 | J6: G层仓库 | K6: Hoàng 范范 | L6: 2025.10.15 | M6: =N6/H6 -> 27 | N6: {=SUMPRODUCT(($A$3:$A$997=A6)*($I$3:$I$997))-SUMPRODUCT((Xuất出库!$A$2:$A$986=A6)*(Xuất出库!$E$2:$E$986))-SUMPRODUCT((Xuất出库!$A$2:$A$986=A6)*(Xuất出库!$F$2:$F$986))+SUMPRODUCT((Hoàn回库!$A$2:$A$996=A6)*(Hoàn回库!$E$2:$E$996))+SUMPRODUCT((Hoàn回库!$A$2:$A$996=A6)*(Hoàn回库!$F$2:$F$996))} -> 27
A7: =VLOOKUP($C7,SKU!$A:$I,3,FALSE) -> 10005 | B7: =VLOOKUP($C7,SKU!$A:$I,2,FALSE) -> 椿柚文创宫崎骏 被风吹散的秘密邮票第一弹 | C7: Gibli Wind | D7: =VLOOKUP($C7,SKU!$A:$I,4,FALSE) -> Card/邮票 | E7: =VLOOKUP($C7,SKU!$A:$I,5,FALSE) -> 椿柚文创 | F7: 1 | G7: =VLOOKUP($C7,SKU!$A:$I,6,FALSE) -> 100 | H7: =VLOOKUP($C7,SKU!$A:$I,7,FALSE) -> 1 | I7: =F7*G7*H7 -> 100 | J7: G层仓库 | K7: Hoàng 范范 | L7: 2025.10.15 | M7: =N7/H7 -> 0 | N7: {=SUMPRODUCT(($A$3:$A$997=A7)*($I$3:$I$997))-SUMPRODUCT((Xuất出库!$A$2:$A$986=A7)*(Xuất出库!$E$2:$E$986))-SUMPRODUCT((Xuất出库!$A$2:$A$986=A7)*(Xuất出库!$F$2:$F$986))+SUMPRODUCT((Hoàn回库!$A$2:$A$996=A7)*(Hoàn回库!$E$2:$E$996))+SUMPRODUCT((Hoàn回库!$A$2:$A$996=A7)*(Hoàn回库!$F$2:$F$996))} -> 0
A8: =VLOOKUP($C8,SKU!$A:$I,3,FALSE) -> 10006 | B8: =VLOOKUP($C8,SKU!$A:$I,2,FALSE) -> 云映文化「云之境の夏」第二弹·宫崎骏珍藏卡牌 | C8: Mây và Hạ | D8: =VLOOKUP($C8,SKU!$A:$I,4,FALSE) -> Card/卡牌 | E8: =VLOOKUP($C8,SKU!$A:$I,5,FALSE) -> 云映文化 | F8: 2 | G8: =VLOOKUP($C8,SKU!$A:$I,6,FALSE) -> 36 | H8: =VLOOKUP($C8,SKU!$A:$I,7,FALSE) -> 13 | I8: =F8*G8*H8 -> 936 | J8: G层仓库 | K8: Hoàng 范范 | L8: 2025.10.15 | M8: =N8/H8 -> -5 | N8: {=SUMPRODUCT(($A$3:$A$997=A8)*($I$3:$I$997))-SUMPRODUCT((Xuất出库!$A$2:$A$986=A8)*(Xuất出库!$E$2:$E$986))-SUMPRODUCT((Xuất出库!$A$2:$A$986=A8)*(Xuất出库!$F$2:$F$986))+SUMPRODUCT((Hoàn回库!$A$2:$A$996=A8)*(Hoàn回库!$E$2:$E$996))+SUMPRODUCT((Hoàn回库!$A$2:$A$996=A8)*(Hoàn回库!$F$2:$F$996))} -> -65
A9: =VLOOKUP($C9,SKU!$A:$I,3,FALSE) -> 10007 | B9: =VLOOKUP($C9,SKU!$A:$I,2,FALSE) -> kawaii宫崎骏梦幻之国 | C9: Kawaii Gibli | D9: =VLOOKUP($C9,SKU!$A:$I,4,FALSE) -> Card/卡牌 | E9: =VLOOKUP($C9,SKU!$A:$I,5,FALSE) -> kawaii | F9: 2 | G9: =VLOOKUP($C9,SKU!$A:$I,6,FALSE) -> 36 | H9: =VLOOKUP($C9,SKU!$A:$I,7,FALSE) -> 13 | I9: =F9*G9*H9 -> 936 | J9: G层仓库 | K9: Hoàng 范范 | L9: 2025.10.15 | M9: =N9/H9 -> 0 | N9: {=SUMPRODUCT(($A$3:$A$997=A9)*($I$3:$I$997))-SUMPRODUCT((Xuất出库!$A$2:$A$986=A9)*(Xuất出库!$E$2:$E$986))-SUMPRODUCT((Xuất出库!$A$2:$A$986=A9)*(Xuất出库!$F$2:$F$986))+SUMPRODUCT((Hoàn回库!$A$2:$A$996=A9)*(Hoàn回库!$E$2:$E$996))+SUMPRODUCT((Hoàn回库!$A$2:$A$996=A9)*(Hoàn回库!$F$2:$F$996))} -> 0
A10: =VLOOKUP($C10,SKU!$A:$I,3,FALSE) -> 10008 | B10: =VLOOKUP($C10,SKU!$A:$I,2,FALSE) -> XWork美少女战士-璀璨之梦 | C10: X work Sailor Moon | D10: =VLOOKUP($C10,SKU!$A:$I,4,FALSE) -> Card/卡牌 | E10: =VLOOKUP($C10,SKU!$A:$I,5,FALSE) -> XWork | F10: 2 | G10: =VLOOKUP($C10,SKU!$A:$I,6,FALSE) -> 36 | H10: =VLOOKUP($C10,SKU!$A:$I,7,FALSE) -> 10 | I10: =F10*G10*H10 -> 720 | J10: G层仓库 | K10: Hoàng 范范 | L10: 2025.10.15 | M10: =N10/H10 -> 0 | N10: {=SUMPRODUCT(($A$3:$A$997=A10)*($I$3:$I$997))-SUMPRODUCT((Xuất出库!$A$2:$A$986=A10)*(Xuất出库!$E$2:$E$986))-SUMPRODUCT((Xuất出库!$A$2:$A$986=A10)*(Xuất出库!$F$2:$F$986))+SUMPRODUCT((Hoàn回库!$A$2:$A$996=A10)*(Hoàn回库!$E$2:$E$996))+SUMPRODUCT((Hoàn回库!$A$2:$A$996=A10)*(Hoàn回库!$F$2:$F$996))} -> 0
A11: =VLOOKUP($C11,SKU!$A:$I,3,FALSE) -> 10009 | B11: =VLOOKUP($C11,SKU!$A:$I,2,FALSE) -> 万画云游三丽鸥家族百变cos收藏卡 | C11: Vancard Sanrio | D11: =VLOOKUP($C11,SKU!$A:$I,4,FALSE) -> Card/卡牌 | E11: =VLOOKUP($C11,SKU!$A:$I,5,FALSE) -> 万画云游 | F11: 1 | G11: =VLOOKUP($C11,SKU!$A:$I,6,FALSE) -> 24 | H11: =VLOOKUP($C11,SKU!$A:$I,7,FALSE) -> 10 | I11: =F11*G11*H11 -> 240 | J11: G层仓库 | K11: Hoàng 范范 | L11: 2025.10.15 | M11: =N11/H11 -> 0 | N11: {=SUMPRODUCT(($A$3:$A$997=A11)*($I$3:$I$997))-SUMPRODUCT((Xuất出库!$A$2:$A$986=A11)*(Xuất出库!$E$2:$E$986))-SUMPRODUCT((Xuất出库!$A$2:$A$986=A11)*(Xuất出库!$F$2:$F$986))+SUMPRODUCT((Hoàn回库!$A$2:$A$996=A11)*(Hoàn回库!$E$2:$E$996))+SUMPRODUCT((Hoàn回库!$A$2:$A$996=A11)*(Hoàn回库!$F$2:$F$996))} -> 0
A12: =VLOOKUP($C12,SKU!$A:$I,3,FALSE) -> 10010 | B12: =VLOOKUP($C12,SKU!$A:$I,2,FALSE) -> 玩的入迷-魔卡少女樱第一弹—樱之绮遇 | C12: Wamder Roaming Sakura | D12: =VLOOKUP($C12,SKU!$A:$I,4,FALSE) -> Card/卡牌 | E12: =VLOOKUP($C12,SKU!$A:$I,5,FALSE) -> 玩的入迷 | F12: 1 | G12: =VLOOKUP($C12,SKU!$A:$I,6,FALSE) -> 36 | H12: =VLOOKUP($C12,SKU!$A:$I,7,FALSE) -> 13 | I12: =F12*G12*H12 -> 468 | J12: G层仓库 | K12: Hoàng 范范 | L12: 2025.10.15 | M12: =N12/H12 -> 0 | N12: {=SUMPRODUCT(($A$3:$A$997=A12)*($I$3:$I$997))-SUMPRODUCT((Xuất出库!$A$2:$A$986=A12)*(Xuất出库!$E$2:$E$986))-SUMPRODUCT((Xuất出库!$A$2:$A$986=A12)*(Xuất出库!$F$2:$F$986))+SUMPRODUCT((Hoàn回库!$A$2:$A$996=A12)*(Hoàn回库!$E$2:$E$996))+SUMPRODUCT((Hoàn回库!$A$2:$A$996=A12)*(Hoàn回库!$F$2:$F$996))} -> 0
A13: =VLOOKUP($C13,SKU!$A:$I,3,FALSE) -> 10011 | B13: =VLOOKUP($C13,SKU!$A:$I,2,FALSE) -> 灿卡文创宫崎骏第二弹《花涧物语》 | C13: Gibli Hoa | D13: =VLOOKUP($C13,SKU!$A:$I,4,FALSE) -> Card/卡牌 | E13: =VLOOKUP($C13,SKU!$A:$I,5,FALSE) -> 灿卡文创 | F13: 2 | G13: =VLOOKUP($C13,SKU!$A:$I,6,FALSE) -> 36 | H13: =VLOOKUP($C13,SKU!$A:$I,7,FALSE) -> 13 | I13: =F13*G13*H13 -> 936 | J13: G层仓库 | K13: Hoàng 范范 | L13: 2025.10.15 | M13: =N13/H13 -> 0 | N13: {=SUMPRODUCT(($A$3:$A$997=A13)*($I$3:$I$997))-SUMPRODUCT((Xuất出库!$A$2:$A$986=A13)*(Xuất出库!$E$2:$E$986))-SUMPRODUCT((Xuất出库!$A$2:$A$986=A13)*(Xuất出库!$F$2:$F$986))+SUMPRODUCT((Hoàn回库!$A$2:$A$996=A13)*(Hoàn回库!$E$2:$E$996))+SUMPRODUCT((Hoàn回库!$A$2:$A$996=A13)*(Hoàn回库!$F$2:$F$996))} -> 0
A14: =VLOOKUP($C14,SKU!$A:$I,3,FALSE) -> 10012 | B14: =VLOOKUP($C14,SKU!$A:$I,2,FALSE) -> 卡文化进击的巨人 | C14: Attack on Titan | D14: =VLOOKUP($C14,SKU!$A:$I,4,FALSE) -> Card/卡牌 | E14: =VLOOKUP($C14,SKU!$A:$I,5,FALSE) -> 卡文化 | F14: 1 | G14: =VLOOKUP($C14,SKU!$A:$I,6,FALSE) -> 48 | H14: =VLOOKUP($C14,SKU!$A:$I,7,FALSE) -> 30 | I14: =F14*G14*H14 -> 1440 | J14: G层仓库 | K14: Hoàng 范范 | L14: 2025.10.15 | M14: =N14/H14 -> 10 | N14: {=SUMPRODUCT(($A$3:$A$997=A14)*($I$3:$I$997))-SUMPRODUCT((Xuất出库!$A$2:$A$986=A14)*(Xuất出库!$E$2:$E$986))-SUMPRODUCT((Xuất出库!$A$2:$A$986=A14)*(Xuất出库!$F$2:$F$986))+SUMPRODUCT((Hoàn回库!$A$2:$A$996=A14)*(Hoàn回库!$E$2:$E$996))+SUMPRODUCT((Hoàn回库!$A$2:$A$996=A14)*(Hoàn回库!$F$2:$F$996))} -> 300
... A22: =VLOOKUP($C22,SKU!$A:$I,3,FALSE) -> 10021 | B22: =VLOOKUP($C22,SKU!$A:$I,2,FALSE) -> 新谷动漫名侦探柯南·仲夏夜之恋邮票集 | C22: Shingu Conan phiếu tem | D22: =VLOOKUP($C22,SKU!$A:$I,4,FALSE) -> Phiếu tem/邮票 | E22: =VLOOKUP($C22,SKU!$A:$I,5,FALSE) -> 新谷动漫 | F22: 2 | G22: =VLOOKUP($C22,SKU!$A:$I,6,FALSE) -> 25 | H22: =VLOOKUP($C22,SKU!$A:$I,7,FALSE) -> 5 | I22: =F22*G22*H22 -> 250 | J22: G层仓库 | K22: Hoàng 范范 | L22: 2025.10.17 | M22: =N22/H22 -> 11 | N22: {=SUMPRODUCT(($A$3:$A$997=A22)*($I$3:$I$997))-SUMPRODUCT((Xuất出库!$A$2:$A$986=A22)*(Xuất出库!$E$2:$E$986))-SUMPRODUCT((Xuất出库!$A$2:$A$986=A22)*(Xuất出库!$F$2:$F$986))+SUMPRODUCT((Hoàn回库!$A$2:$A$996=A22)*(Hoàn回库!$E$2:$E$996))+SUMPRODUCT((Hoàn回库!$A$2:$A$996=A22)*(Hoàn回库!$F$2:$F$996))} -> 55
A23: =VLOOKUP($C23,SKU!$A:$I,3,FALSE) -> 10022 | B23: =VLOOKUP($C23,SKU!$A:$I,2,FALSE) -> 【耀光·美少女战士】长卡卡砖 | C23: Sailor Shining | D23: =VLOOKUP($C23,SKU!$A:$I,4,FALSE) -> Thẻ hộp/卡砖 | E23: =VLOOKUP($C23,SKU!$A:$I,5,FALSE) -> 耀光 | F23: 1 | G23: 24 | H23: 8 | I23: =F23*G23*H23 -> 192 | J23: G层仓库 | K23: Hoàng 范范 | L23: 2025.10.17 | M23: =N23/H23 -> 0 | N23: {=SUMPRODUCT(($A$3:$A$997=A23)*($I$3:$I$997))-SUMPRODUCT((Xuất出库!$A$2:$A$986=A23)*(Xuất出库!$E$2:$E$986))-SUMPRODUCT((Xuất出库!$A$2:$A$986=A23)*(Xuất出库!$F$2:$F$986))+SUMPRODUCT((Hoàn回库!$A$2:$A$996=A23)*(Hoàn回库!$E$2:$E$996))+SUMPRODUCT((Hoàn回库!$A$2:$A$996=A23)*(Hoàn回库!$F$2:$F$996))} -> 0
A24: =VLOOKUP($C24,SKU!$A:$I,3,FALSE) -> 10023 | B24: =VLOOKUP($C24,SKU!$A:$I,2,FALSE) -> 风信文创尘世相逢之约星光来信原神邮票第一弹 | C24: Tinh quang Genshin | D24: =VLOOKUP($C24,SKU!$A:$I,4,FALSE) -> Phiếu tem/邮票 | E24: =VLOOKUP($C24,SKU!$A:$I,5,FALSE) -> 风信文创 | F24: 1 | G24: =VLOOKUP($C24,SKU!$A:$I,6,FALSE) -> 100 | H24: =VLOOKUP($C24,SKU!$A:$I,7,FALSE) -> 1 | I24: =F24*G24*H24 -> 100 | J24: G层仓库 | K24: Hoàng 范范 | L24: 2025.10.17 | M24: =N24/H24 -> 20 | N24: {=SUMPRODUCT(($A$3:$A$997=A24)*($I$3:$I$997))-SUMPRODUCT((Xuất出库!$A$2:$A$986=A24)*(Xuất出库!$E$2:$E$986))-SUMPRODUCT((Xuất出库!$A$2:$A$986=A24)*(Xuất出库!$F$2:$F$986))+SUMPRODUCT((Hoàn回库!$A$2:$A$996=A24)*(Hoàn回库!$E$2:$E$996))+SUMPRODUCT((Hoàn回库!$A$2:$A$996=A24)*(Hoàn回库!$F$2:$F$996))} -> 20
A25: =VLOOKUP($C25,SKU!$A:$I,3,FALSE) -> 10024 | B25: =VLOOKUP($C25,SKU!$A:$I,2,FALSE) -> 漫影工作室-柯南-A5 大卡第一弹 | C25: Conan đám cưới A5 vol 1 | D25: =VLOOKUP($C25,SKU!$A:$I,4,FALSE) -> Thẻ bự/色纸 | E25: =VLOOKUP($C25,SKU!$A:$I,5,FALSE) -> 漫影工作室 | F25: 1 | G25: =VLOOKUP($C25,SKU!$A:$I,6,FALSE) -> 50 | H25: =VLOOKUP($C25,SKU!$A:$I,7,FALSE) -> 1 | I25: =F25*G25*H25 -> 50 | J25: G层仓库 | K25: Hoàng 范范 | L25: 2025.10.17 | M25: =N25/H25 -> 13 | N25: {=SUMPRODUCT(($A$3:$A$997=A25)*($I$3:$I$997))-SUMPRODUCT((Xuất出库!$A$2:$A$986=A25)*(Xuất出库!$E$2:$E$986))-SUMPRODUCT((Xuất出库!$A$2:$A$986=A25)*(Xuất出库!$F$2:$F$986))+SUMPRODUCT((Hoàn回库!$A$2:$A$996=A25)*(Hoàn回库!$E$2:$E$996))+SUMPRODUCT((Hoàn回库!$A$2:$A$996=A25)*(Hoàn回库!$F$2:$F$996))} -> 13
A26: =VLOOKUP($C26,SKU!$A:$I,3,FALSE) -> 10025 | B26: =VLOOKUP($C26,SKU!$A:$I,2,FALSE) -> 君屹文化耽美古风收藏新纪元《言辞忆梦》撕撕乐 | C26: Quân sơn TQTP | D26: =VLOOKUP($C26,SKU!$A:$I,4,FALSE) -> Thẻ xé/撕撕乐 | E26: =VLOOKUP($C26,SKU!$A:$I,5,FALSE) -> 君屹文化 | F26: 2 | G26: =VLOOKUP($C26,SKU!$A:$I,6,FALSE) -> 300 | H26: =VLOOKUP($C26,SKU!$A:$I,7,FALSE) -> 1 | I26: =F26*G26*H26 -> 600 | J26: G层仓库 | K26: Hoàng 范范 | L26: 2025.10.17 | M26: =N26/H26 -> 0 | N26: {=SUMPRODUCT(($A$3:$A$997=A26)*($I$3:$I$997))-SUMPRODUCT((Xuất出库!$A$2:$A$986=A26)*(Xuất出库!$E$2:$E$986))-SUMPRODUCT((Xuất出库!$A$2:$A$986=A26)*(Xuất出库!$F$2:$F$986))+SUMPRODUCT((Hoàn回库!$A$2:$A$996=A26)*(Hoàn回库!$E$2:$E$996))+SUMPRODUCT((Hoàn回库!$A$2:$A$996=A26)*(Hoàn回库!$F$2:$F$996))} -> 0
A27: =VLOOKUP($C27,SKU!$A:$I,3,FALSE) -> 10026 | B27: =VLOOKUP($C27,SKU!$A:$I,2,FALSE) -> 星恋文创·恋与深空《晦明交错之间》亚克力相框卡 | C27: Hải Minh LnD | D27: =VLOOKUP($C27,SKU!$A:$I,4,FALSE) -> Thẻ bự/色纸 | E27: =VLOOKUP($C27,SKU!$A:$I,5,FALSE) -> 星恋文创 | F27: 2 | G27: =VLOOKUP($C27,SKU!$A:$I,6,FALSE) -> 100 | H27: =VLOOKUP($C27,SKU!$A:$I,7,FALSE) -> 1 | I27: =F27*G27*H27 -> 200 | J27: G层仓库 | K27: Hoàng 范范 | L27: 2025.10.17 | M27: =N27/H27 -> 29 | N27: {=SUMPRODUCT(($A$3:$A$997=A27)*($I$3:$I$997))-SUMPRODUCT((Xuất出库!$A$2:$A$986=A27)*(Xuất出库!$E$2:$E$986))-SUMPRODUCT((Xuất出库!$A$2:$A$986=A27)*(Xuất出库!$F$2:$F$986))+SUMPRODUCT((Hoàn回库!$A$2:$A$996=A27)*(Hoàn回库!$E$2:$E$996))+SUMPRODUCT((Hoàn回库!$A$2:$A$996=A27)*(Hoàn回库!$F$2:$F$996))} -> 29
A28: =VLOOKUP($C28,SKU!$A:$I,3,FALSE) -> 10027 | B28: =VLOOKUP($C28,SKU!$A:$I,2,FALSE) -> 深空绘约文创我不爱世界只爱你邮票撕拉卡 | C28: LnD phiếu tem | D28: =VLOOKUP($C28,SKU!$A:$I,4,FALSE) -> Phiếu tem/邮票 | E28: =VLOOKUP($C28,SKU!$A:$I,5,FALSE) -> 深空绘约文创 | F28: 1 | G28: =VLOOKUP($C28,SKU!$A:$I,6,FALSE) -> 30 | H28: =VLOOKUP($C28,SKU!$A:$I,7,FALSE) -> 6 | I28: =F28*G28*H28 -> 180 | J28: G层仓库 | K28: Hoàng 范范 | L28: 2025.10.17 | M28: =N28/H28 -> 30 | N28: {=SUMPRODUCT(($A$3:$A$997=A28)*($I$3:$I$997))-SUMPRODUCT((Xuất出库!$A$2:$A$986=A28)*(Xuất出库!$E$2:$E$986))-SUMPRODUCT((Xuất出库!$A$2:$A$986=A28)*(Xuất出库!$F$2:$F$986))+SUMPRODUCT((Hoàn回库!$A$2:$A$996=A28)*(Hoàn回库!$E$2:$E$996))+SUMPRODUCT((Hoàn回库!$A$2:$A$996=A28)*(Hoàn回库!$F$2:$F$996))} -> 180
A29: =VLOOKUP($C29,SKU!$A:$I,3,FALSE) -> 10028 | B29: =VLOOKUP($C29,SKU!$A:$I,2,FALSE) -> 潮玩咔原神 尘世收藏卡 | C29: Trendy Toyka Genshin | D29: =VLOOKUP($C29,SKU!$A:$I,4,FALSE) -> Card/卡牌 | E29: =VLOOKUP($C29,SKU!$A:$I,5,FALSE) -> 潮玩咔 | F29: 1 | G29: =VLOOKUP($C29,SKU!$A:$I,6,FALSE) -> 36 | H29: =VLOOKUP($C29,SKU!$A:$I,7,FALSE) -> 13 | I29: =F29*G29*H29 -> 468 | J29: G层仓库 | K29: Hoàng 范范 | L29: 2025.10.17 | M29: =N29/H29 -> 5 | N29: {=SUMPRODUCT(($A$3:$A$997=A29)*($I$3:$I$997))-SUMPRODUCT((Xuất出库!$A$2:$A$986=A29)*(Xuất出库!$E$2:$E$986))-SUMPRODUCT((Xuất出库!$A$2:$A$986=A29)*(Xuất出库!$F$2:$F$986))+SUMPRODUCT((Hoàn回库!$A$2:$A$996=A29)*(Hoàn回库!$E$2:$E$996))+SUMPRODUCT((Hoàn回库!$A$2:$A$996=A29)*(Hoàn回库!$F$2:$F$996))} -> 65
A30: =VLOOKUP($C30,SKU!$A:$I,3,FALSE) -> 10029 | B30: =VLOOKUP($C30,SKU!$A:$I,2,FALSE) -> 樱花屋魔卡少女樱 | C30: Sakura House | D30: =VLOOKUP($C30,SKU!$A:$I,4,FALSE) -> Card/卡牌 | E30: =VLOOKUP($C30,SKU!$A:$I,5,FALSE) -> 樱花屋 | F30: 1 | G30: =VLOOKUP($C30,SKU!$A:$I,6,FALSE) -> 49 | H30: =VLOOKUP($C30,SKU!$A:$I,7,FALSE) -> 12 | I30: =F30*G30*H30 -> 588 | J30: G层仓库 | K30: Hoàng 范范 | L30: 2025.10.17 | M30: =N30/H30 -> -6.75 | N30: {=SUMPRODUCT(($A$3:$A$997=A30)*($I$3:$I$997))-SUMPRODUCT((Xuất出库!$A$2:$A$986=A30)*(Xuất出库!$E$2:$E$986))-SUMPRODUCT((Xuất出库!$A$2:$A$986=A30)*(Xuất出库!$F$2:$F$986))+SUMPRODUCT((Hoàn回库!$A$2:$A$996=A30)*(Hoàn回库!$E$2:$E$996))+SUMPRODUCT((Hoàn回库!$A$2:$A$996=A30)*(Hoàn回库!$F$2:$F$996))} -> -81
A31: =VLOOKUP($C31,SKU!$A:$I,3,FALSE) -> 10030 | B31: =VLOOKUP($C31,SKU!$A:$I,2,FALSE) -> 梦影动漫黑执事-典藏版收藏卡牌 | C31: Mộng ảnh Hắc Quản Gia | D31: =VLOOKUP($C31,SKU!$A:$I,4,FALSE) -> Card/卡牌 | E31: =VLOOKUP($C31,SKU!$A:$I,5,FALSE) -> 梦影动漫 | F31: 1 | G31: =VLOOKUP($C31,SKU!$A:$I,6,FALSE) -> 36 | H31: =VLOOKUP($C31,SKU!$A:$I,7,FALSE) -> 12 | I31: =F31*G31*H31 -> 432 | J31: G层仓库 | K31: Hoàng 范范 | L31: 2025.10.17 | M31: =N31/H31 -> 0 | N31: {=SUMPRODUCT(($A$3:$A$997=A31)*($I$3:$I$997))-SUMPRODUCT((Xuất出库!$A$2:$A$986=A31)*(Xuất出库!$E$2:$E$986))-SUMPRODUCT((Xuất出库!$A$2:$A$986=A31)*(Xuất出库!$F$2:$F$986))+SUMPRODUCT((Hoàn回库!$A$2:$A$996=A31)*(Hoàn回库!$E$2:$E$996))+SUMPRODUCT((Hoàn回库!$A$2:$A$996=A31)*(Hoàn回库!$F$2:$F$996))} -> 0
A32: =VLOOKUP($C32,SKU!$A:$I,3,FALSE) -> 10031 | B32: =VLOOKUP($C32,SKU!$A:$I,2,FALSE) -> 胜卡文创x魔道祖师云深不忘邮票评级卡砖 | C32: SK MĐTS phiếu tem | D32: =VLOOKUP($C32,SKU!$A:$I,4,FALSE) -> Phiếu tem/邮票 | E32: =VLOOKUP($C32,SKU!$A:$I,5,FALSE) -> 胜卡文创 | F32: 2 | G32: =VLOOKUP($C32,SKU!$A:$I,6,FALSE) -> 12 | H32: =VLOOKUP($C32,SKU!$A:$I,7,FALSE) -> 10 | I32: =F32*G32*H32 -> 240 | J32: G层仓库 | K32: Hoàng 范范 | L32: 2025.10.17 | M32: =N32/H32 -> 2 | N32: {=SUMPRODUCT(($A$3:$A$997=A32)*($I$3:$I$997))-SUMPRODUCT((Xuất出库!$A$2:$A$986=A32)*(Xuất出库!$E$2:$E$986))-SUMPRODUCT((Xuất出库!$A$2:$A$986=A32)*(Xuất出库!$F$2:$F$986))+SUMPRODUCT((Hoàn回库!$A$2:$A$996=A32)*(Hoàn回库!$E$2:$E$996))+SUMPRODUCT((Hoàn回库!$A$2:$A$996=A32)*(Hoàn回库!$F$2:$F$996))} -> 20
A33: =VLOOKUP($C33,SKU!$A:$I,3,FALSE) -> 10032 | B33: =VLOOKUP($C33,SKU!$A:$I,2,FALSE) -> 绘心阁《魔道祖师—殊途同归》色纸卡牌 | C33: Huixin MĐTS | D33: =VLOOKUP($C33,SKU!$A:$I,4,FALSE) -> Thẻ bự/色纸 | E33: =VLOOKUP($C33,SKU!$A:$I,5,FALSE) -> 绘心阁 | F33: 2 | G33: =VLOOKUP($C33,SKU!$A:$I,6,FALSE) -> 180 | H33: =VLOOKUP($C33,SKU!$A:$I,7,FALSE) -> 1 | I33: =F33*G33*H33 -> 360 | J33: G层仓库 | K33: Hoàng 范范 | L33: 2025.10.17 | M33: =N33/H33 -> 0 | N33: {=SUMPRODUCT(($A$3:$A$997=A33)*($I$3:$I$997))-SUMPRODUCT((Xuất出库!$A$2:$A$986=A33)*(Xuất出库!$E$2:$E$986))-SUMPRODUCT((Xuất出库!$A$2:$A$986=A33)*(Xuất出库!$F$2:$F$986))+SUMPRODUCT((Hoàn回库!$A$2:$A$996=A33)*(Hoàn回库!$E$2:$E$996))+SUMPRODUCT((Hoàn回库!$A$2:$A$996=A33)*(Hoàn回库!$F$2:$F$996))} -> 0
A34: =VLOOKUP($C34,SKU!$A:$I,3,FALSE) -> 10033 | B34: =VLOOKUP($C34,SKU!$A:$I,2,FALSE) -> 慕光文创「一千次心动」系列撕撕乐 | C34: LnD thẻ xé Ngàn lần động tâm | D34: =VLOOKUP($C34,SKU!$A:$I,4,FALSE) -> Thẻ xé/撕撕乐 | E34: =VLOOKUP($C34,SKU!$A:$I,5,FALSE) -> 慕光文创 | F34: 2 | G34: =VLOOKUP($C34,SKU!$A:$I,6,FALSE) -> 150 | H34: =VLOOKUP($C34,SKU!$A:$I,7,FALSE) -> 1 | I34: =F34*G34*H34 -> 300 | J34: G层仓库 | K34: Hoàng 范范 | L34: 2025.10.17 | M34: =N34/H34 -> 199 | N34: {=SUMPRODUCT(($A$3:$A$997=A34)*($I$3:$I$997))-SUMPRODUCT((Xuất出库!$A$2:$A$986=A34)*(Xuất出库!$E$2:$E$986))-SUMPRODUCT((Xuất出库!$A$2:$A$986=A34)*(Xuất出库!$F$2:$F$986))+SUMPRODUCT((Hoàn回库!$A$2:$A$996=A34)*(Hoàn回库!$E$2:$E$996))+SUMPRODUCT((Hoàn回库!$A$2:$A$996=A34)*(Hoàn回库!$F$2:$F$996))} -> 199
A35: =VLOOKUP($C35,SKU!$A:$I,3,FALSE) -> 10034 | B35: =VLOOKUP($C35,SKU!$A:$I,2,FALSE) -> 兰亭文创x墨家三宝典藏色纸砚池春深系列 | C35: Lan Đình A6 tổng hợp | D35: =VLOOKUP($C35,SKU!$A:$I,4,FALSE) -> Thẻ bự/色纸 | E35: =VLOOKUP($C35,SKU!$A:$I,5,FALSE) -> 兰亭文创 | F35: 2 | G35: =VLOOKUP($C35,SKU!$A:$I,6,FALSE) -> 120 | H35: =VLOOKUP($C35,SKU!$A:$I,7,FALSE) -> 1 | I35: =F35*G35*H35 -> 240 | J35: G层仓库 | K35: Hoàng 范范 | L35: 2025.10.17 | M35: =N35/H35 -> 0 | N35: {=SUMPRODUCT(($A$3:$A$997=A35)*($I$3:$I$997))-SUMPRODUCT((Xuất出库!$A$2:$A$986=A35)*(Xuất出库!$E$2:$E$986))-SUMPRODUCT((Xuất出库!$A$2:$A$986=A35)*(Xuất出库!$F$2:$F$986))+SUMPRODUCT((Hoàn回库!$A$2:$A$996=A35)*(Hoàn回库!$E$2:$E$996))+SUMPRODUCT((Hoàn回库!$A$2:$A$996=A35)*(Hoàn回库!$F$2:$F$996))} -> 0
... A83: =VLOOKUP($C83,SKU!$A:$I,3,FALSE) -> 10081 | B83: =VLOOKUP($C83,SKU!$A:$I,2,FALSE) -> 京都社 美少女战士 · 第4弹 | C83: Kyoto Sailor Moon vol 4 | D83: =VLOOKUP($C83,SKU!$A:$I,4,FALSE) -> Card/卡牌 | E83: =VLOOKUP($C83,SKU!$A:$I,5,FALSE) -> 京都社 | F83: 1 | G83: =VLOOKUP($C83,SKU!$A:$I,6,FALSE) -> 36 | H83: =VLOOKUP($C83,SKU!$A:$I,7,FALSE) -> 13 | I83: =F83*G83*H83 -> 468 | J83: G层仓库 | K83: Hoàng 范范 | L83: 2025.12.08 | M83: =N83/H83 -> 16 | N83: {=SUMPRODUCT(($A$3:$A$997=A83)*($I$3:$I$997))-SUMPRODUCT((Xuất出库!$A$2:$A$986=A83)*(Xuất出库!$E$2:$E$986))-SUMPRODUCT((Xuất出库!$A$2:$A$986=A83)*(Xuất出库!$F$2:$F$986))+SUMPRODUCT((Hoàn回库!$A$2:$A$996=A83)*(Hoàn回库!$E$2:$E$996))+SUMPRODUCT((Hoàn回库!$A$2:$A$996=A83)*(Hoàn回库!$F$2:$F$996))} -> 208
A84: =VLOOKUP($C84,SKU!$A:$I,3,FALSE) -> 10082 | B84: =VLOOKUP($C84,SKU!$A:$I,2,FALSE) -> 吾羽文创-全亚克力正方形原神色纸 | C84: Genshin A6 Tiwayimeng (Viết tắt Tiwa) | D84: =VLOOKUP($C84,SKU!$A:$I,4,FALSE) -> Thẻ bự/色纸 | E84: =VLOOKUP($C84,SKU!$A:$I,5,FALSE) -> 吾羽文创 | F84: =1+179/180 -> 1.9944444 | G84: =VLOOKUP($C84,SKU!$A:$I,6,FALSE) -> 30 | H84: =VLOOKUP($C84,SKU!$A:$I,7,FALSE) -> 6 | I84: =F84*G84*H84 -> 359 | J84: G层仓库 | K84: Hoàng 范范 | L84: 2025.12.08 | M84: =N84/H84 -> -1.7053026e-13 | N84: {=SUMPRODUCT(($A$3:$A$997=A84)*($I$3:$I$997))-SUMPRODUCT((Xuất出库!$A$2:$A$986=A84)*(Xuất出库!$E$2:$E$986))-SUMPRODUCT((Xuất出库!$A$2:$A$986=A84)*(Xuất出库!$F$2:$F$986))+SUMPRODUCT((Hoàn回库!$A$2:$A$996=A84)*(Hoàn回库!$E$2:$E$996))+SUMPRODUCT((Hoàn回库!$A$2:$A$996=A84)*(Hoàn回库!$F$2:$F$996))} -> -1.0231815e-12
A85: =VLOOKUP($C85,SKU!$A:$I,3,FALSE) -> 10083 | B85: =VLOOKUP($C85,SKU!$A:$I,2,FALSE) -> 天官赐福花灯照夜 | C85: Card Fun Thiên quan tứ phúc Hoa đăng chiếu dạ | D85: =VLOOKUP($C85,SKU!$A:$I,4,FALSE) -> Card/卡牌 | E85: =VLOOKUP($C85,SKU!$A:$I,5,FALSE) -> 集卡社 | F85: 1 | G85: =VLOOKUP($C85,SKU!$A:$I,6,FALSE) -> 36 | H85: =VLOOKUP($C85,SKU!$A:$I,7,FALSE) -> 16 | I85: =F85*G85*H85 -> 576 | J85: G层仓库 | K85: Hoàng 范范 | L85: 2025.12.08 | M85: =N85/H85 -> 16 | N85: {=SUMPRODUCT(($A$3:$A$997=A85)*($I$3:$I$997))-SUMPRODUCT((Xuất出库!$A$2:$A$986=A85)*(Xuất出库!$E$2:$E$986))-SUMPRODUCT((Xuất出库!$A$2:$A$986=A85)*(Xuất出库!$F$2:$F$986))+SUMPRODUCT((Hoàn回库!$A$2:$A$996=A85)*(Hoàn回库!$E$2:$E$996))+SUMPRODUCT((Hoàn回库!$A$2:$A$996=A85)*(Hoàn回库!$F$2:$F$996))} -> 256
A86: =VLOOKUP($C86,SKU!$A:$I,3,FALSE) -> 10084 | B86: =VLOOKUP($C86,SKU!$A:$I,2,FALSE) -> 《斩神之凡尘神域》典藏版收藏卡 | C86: Card Fun Trảm thần chi phàm trần thần vực | D86: =VLOOKUP($C86,SKU!$A:$I,4,FALSE) -> Card/卡牌 | E86: =VLOOKUP($C86,SKU!$A:$I,5,FALSE) -> 集卡社 | F86: 1 | G86: =VLOOKUP($C86,SKU!$A:$I,6,FALSE) -> 36 | H86: =VLOOKUP($C86,SKU!$A:$I,7,FALSE) -> 16 | I86: =F86*G86*H86 -> 576 | J86: G层仓库 | K86: Hoàng 范范 | L86: 2025.12.08 | M86: =N86/H86 -> 36 | N86: {=SUMPRODUCT(($A$3:$A$997=A86)*($I$3:$I$997))-SUMPRODUCT((Xuất出库!$A$2:$A$986=A86)*(Xuất出库!$E$2:$E$986))-SUMPRODUCT((Xuất出库!$A$2:$A$986=A86)*(Xuất出库!$F$2:$F$986))+SUMPRODUCT((Hoàn回库!$A$2:$A$996=A86)*(Hoàn回库!$E$2:$E$996))+SUMPRODUCT((Hoàn回库!$A$2:$A$996=A86)*(Hoàn回库!$F$2:$F$996))} -> 576
A87: =VLOOKUP($C87,SKU!$A:$I,3,FALSE) -> 10085 | B87: =VLOOKUP($C87,SKU!$A:$I,2,FALSE) -> 火影忍者·手绘复刻撕撕乐 | C87: Naruto thẻ xé | D87: =VLOOKUP($C87,SKU!$A:$I,4,FALSE) -> Thẻ xé/撕撕乐 | E87: =VLOOKUP($C87,SKU!$A:$I,5,FALSE) -> 未知 | F87: 2 | G87: =VLOOKUP($C87,SKU!$A:$I,6,FALSE) -> 300 | H87: =VLOOKUP($C87,SKU!$A:$I,7,FALSE) -> 1 | I87: =F87*G87*H87 -> 600 | J87: G层仓库 | K87: Hoàng 范范 | L87: 2025.12.08 | M87: =N87/H87 -> 370 | N87: {=SUMPRODUCT(($A$3:$A$997=A87)*($I$3:$I$997))-SUMPRODUCT((Xuất出库!$A$2:$A$986=A87)*(Xuất出库!$E$2:$E$986))-SUMPRODUCT((Xuất出库!$A$2:$A$986=A87)*(Xuất出库!$F$2:$F$986))+SUMPRODUCT((Hoàn回库!$A$2:$A$996=A87)*(Hoàn回库!$E$2:$E$996))+SUMPRODUCT((Hoàn回库!$A$2:$A$996=A87)*(Hoàn回库!$F$2:$F$996))} -> 370
A88: =VLOOKUP($C88,SKU!$A:$I,3,FALSE) -> 10086 | B88: =VLOOKUP($C88,SKU!$A:$I,2,FALSE) -> 【潮迷文创】名侦探柯南-危险排队-周边创意艺术色纸 | C88: Conan ver Party nguy hiểm | D88: =VLOOKUP($C88,SKU!$A:$I,4,FALSE) -> Thẻ bự/色纸 | E88: =VLOOKUP($C88,SKU!$A:$I,5,FALSE) -> 潮迷文创 | F88: 2 | G88: =VLOOKUP($C88,SKU!$A:$I,6,FALSE) -> 90 | H88: =VLOOKUP($C88,SKU!$A:$I,7,FALSE) -> 1 | I88: =F88*G88*H88 -> 180 | J88: G层仓库 | K88: Hoàng 范范 | L88: 2025.12.08 | M88: =N88/H88 -> 0 | N88: {=SUMPRODUCT(($A$3:$A$997=A88)*($I$3:$I$997))-SUMPRODUCT((Xuất出库!$A$2:$A$986=A88)*(Xuất出库!$E$2:$E$986))-SUMPRODUCT((Xuất出库!$A$2:$A$986=A88)*(Xuất出库!$F$2:$F$986))+SUMPRODUCT((Hoàn回库!$A$2:$A$996=A88)*(Hoàn回库!$E$2:$E$996))+SUMPRODUCT((Hoàn回库!$A$2:$A$996=A88)*(Hoàn回库!$F$2:$F$996))} -> 0
A89: =VLOOKUP($C89,SKU!$A:$I,3,FALSE) -> 10087 | B89: =VLOOKUP($C89,SKU!$A:$I,2,FALSE) -> 世界杯足球2026 | C89: World Cup 2026 | D89: =VLOOKUP($C89,SKU!$A:$I,4,FALSE) -> Card/卡牌 | E89: =VLOOKUP($C89,SKU!$A:$I,5,FALSE) -> 义乌 | F89: 2 | G89: =VLOOKUP($C89,SKU!$A:$I,6,FALSE) -> 80 | H89: =VLOOKUP($C89,SKU!$A:$I,7,FALSE) -> 36 | I89: =F89*G89*H89 -> 5760 | J89: G层仓库 | K89: Hoàng 范范 | L89: 2025.12.08 | M89: =N89/H89 -> 145 | N89: {=SUMPRODUCT(($A$3:$A$997=A89)*($I$3:$I$997))-SUMPRODUCT((Xuất出库!$A$2:$A$986=A89)*(Xuất出库!$E$2:$E$986))-SUMPRODUCT((Xuất出库!$A$2:$A$986=A89)*(Xuất出库!$F$2:$F$986))+SUMPRODUCT((Hoàn回库!$A$2:$A$996=A89)*(Hoàn回库!$E$2:$E$996))+SUMPRODUCT((Hoàn回库!$A$2:$A$996=A89)*(Hoàn回库!$F$2:$F$996))} -> 5220
A90: =VLOOKUP($C90,SKU!$A:$I,3,FALSE) -> 10088 | B90: =VLOOKUP($C90,SKU!$A:$I,2,FALSE) -> 名侦探柯南-名推理收藏卡-觅影包-第3弹 | C90: Kayou Conan vol 3 (bản 2 tệ) | D90: =VLOOKUP($C90,SKU!$A:$I,4,FALSE) -> Thẻ bự/色纸 | E90: =VLOOKUP($C90,SKU!$A:$I,5,FALSE) -> 卡游 | F90: 2 | G90: =VLOOKUP($C90,SKU!$A:$I,6,FALSE) -> 48 | H90: =VLOOKUP($C90,SKU!$A:$I,7,FALSE) -> 30 | I90: =F90*G90*H90 -> 2880 | J90: G层仓库 | K90: Hoàng 范范 | L90: 2025.12.08 | M90: =N90/H90 -> 59 | N90: {=SUMPRODUCT(($A$3:$A$997=A90)*($I$3:$I$997))-SUMPRODUCT((Xuất出库!$A$2:$A$986=A90)*(Xuất出库!$E$2:$E$986))-SUMPRODUCT((Xuất出库!$A$2:$A$986=A90)*(Xuất出库!$F$2:$F$986))+SUMPRODUCT((Hoàn回库!$A$2:$A$996=A90)*(Hoàn回库!$E$2:$E$996))+SUMPRODUCT((Hoàn回库!$A$2:$A$996=A90)*(Hoàn回库!$F$2:$F$996))} -> 1770
A91: =VLOOKUP($C91,SKU!$A:$I,3,FALSE) -> 10031 | B91: =VLOOKUP($C91,SKU!$A:$I,2,FALSE) -> 胜卡文创x魔道祖师云深不忘邮票评级卡砖 | C91: SK MĐTS phiếu tem | D91: =VLOOKUP($C91,SKU!$A:$I,4,FALSE) -> Phiếu tem/邮票 | E91: =VLOOKUP($C91,SKU!$A:$I,5,FALSE) -> 胜卡文创 | F91: =1/6 -> 0.16666667 | G91: =VLOOKUP($C91,SKU!$A:$I,6,FALSE) -> 12 | H91: =VLOOKUP($C91,SKU!$A:$I,7,FALSE) -> 10 | I91: =F91*G91*H91 -> 20 | J91: G层仓库 | K91: Hoàng 范范 | L91: 2025.12.08 | M91: =N91/H91 -> 2 | N91: {=SUMPRODUCT(($A$3:$A$997=A91)*($I$3:$I$997))-SUMPRODUCT((Xuất出库!$A$2:$A$986=A91)*(Xuất出库!$E$2:$E$986))-SUMPRODUCT((Xuất出库!$A$2:$A$986=A91)*(Xuất出库!$F$2:$F$986))+SUMPRODUCT((Hoàn回库!$A$2:$A$996=A91)*(Hoàn回库!$E$2:$E$996))+SUMPRODUCT((Hoàn回库!$A$2:$A$996=A91)*(Hoàn回库!$F$2:$F$996))} -> 20
A92: =VLOOKUP($C92,SKU!$A:$I,3,FALSE) -> 10089 | B92: =VLOOKUP($C92,SKU!$A:$I,2,FALSE) -> 星火线条小狗 | C92: Sao Hỏa Maltese | D92: =VLOOKUP($C92,SKU!$A:$I,4,FALSE) -> Card/卡牌 | E92: =VLOOKUP($C92,SKU!$A:$I,5,FALSE) -> 星火 | F92: 2 | G92: =VLOOKUP($C92,SKU!$A:$I,6,FALSE) -> 36 | H92: =VLOOKUP($C92,SKU!$A:$I,7,FALSE) -> 14 | I92: =F92*G92*H92 -> 1008 | J92: G层仓库 | K92: Hoàng 范范 | L92: 2025.12.12 | M92: =N92/H92 -> 0 | N92: {=SUMPRODUCT(($A$3:$A$997=A92)*($I$3:$I$997))-SUMPRODUCT((Xuất出库!$A$2:$A$986=A92)*(Xuất出库!$E$2:$E$986))-SUMPRODUCT((Xuất出库!$A$2:$A$986=A92)*(Xuất出库!$F$2:$F$986))+SUMPRODUCT((Hoàn回库!$A$2:$A$996=A92)*(Hoàn回库!$E$2:$E$996))+SUMPRODUCT((Hoàn回库!$A$2:$A$996=A92)*(Hoàn回库!$F$2:$F$996))} -> 0
A93: =VLOOKUP($C93,SKU!$A:$I,3,FALSE) -> 10090 | B93: =VLOOKUP($C93,SKU!$A:$I,2,FALSE) -> 依梦×宫崎骏の治愈一生 | C93: Yimeng Ghibli chữa lành cả đời | D93: =VLOOKUP($C93,SKU!$A:$I,4,FALSE) -> Card/卡牌 | E93: =VLOOKUP($C93,SKU!$A:$I,5,FALSE) -> 依梦 | F93: 1 | G93: =VLOOKUP($C93,SKU!$A:$I,6,FALSE) -> 36 | H93: =VLOOKUP($C93,SKU!$A:$I,7,FALSE) -> 13 | I93: =F93*G93*H93 -> 468 | J93: G层仓库 | K93: Hoàng 范范 | L93: 2025.12.12 | M93: =N93/H93 -> 0 | N93: {=SUMPRODUCT(($A$3:$A$997=A93)*($I$3:$I$997))-SUMPRODUCT((Xuất出库!$A$2:$A$986=A93)*(Xuất出库!$E$2:$E$986))-SUMPRODUCT((Xuất出库!$A$2:$A$986=A93)*(Xuất出库!$F$2:$F$986))+SUMPRODUCT((Hoàn回库!$A$2:$A$996=A93)*(Hoàn回库!$E$2:$E$996))+SUMPRODUCT((Hoàn回库!$A$2:$A$996=A93)*(Hoàn回库!$F$2:$F$996))} -> 0
A94: =VLOOKUP($C94,SKU!$A:$I,3,FALSE) -> 10091 | B94: =VLOOKUP($C94,SKU!$A:$I,2,FALSE) -> 星际宝贝百变顽家收藏卡 | C94: Card Fun Lilo&Stitch Dân chơi bách biến | D94: =VLOOKUP($C94,SKU!$A:$I,4,FALSE) -> Card/卡牌 | E94: =VLOOKUP($C94,SKU!$A:$I,5,FALSE) -> 集卡社 | F94: 1 | G94: =VLOOKUP($C94,SKU!$A:$I,6,FALSE) -> 48 | H94: =VLOOKUP($C94,SKU!$A:$I,7,FALSE) -> 10 | I94: =F94*G94*H94 -> 480 | J94: G层仓库 | K94: Hoàng 范范 | L94: 2025.12.12 | M94: =N94/H94 -> 0 | N94: {=SUMPRODUCT(($A$3:$A$997=A94)*($I$3:$I$997))-SUMPRODUCT((Xuất出库!$A$2:$A$986=A94)*(Xuất出库!$E$2:$E$986))-SUMPRODUCT((Xuất出库!$A$2:$A$986=A94)*(Xuất出库!$F$2:$F$986))+SUMPRODUCT((Hoàn回库!$A$2:$A$996=A94)*(Hoàn回库!$E$2:$E$996))+SUMPRODUCT((Hoàn回库!$A$2:$A$996=A94)*(Hoàn回库!$F$2:$F$996))} -> 0
...

Sheet Xuất出库
A1: sku序列 SKU CODE | B1: 中文名 Tên tiếng Trung | C1: 英文/越文名 Tên tiếng Việt | D1: 数量/盒 SL (Hộp) | E1: 整盒包数 SL (Pack/Tổng hộp) | F1: 零散包数 Pack lẻ | G1: 主播 Host | H1: 取货人 Người xuất | I1: 出库日期 Ngày xuất | J1: 时间 Thời gian
A2: =VLOOKUP($C2,SKU!$A:$I,3,FALSE) -> 10010 | B2: =VLOOKUP($C2,SKU!$A:$I,2,FALSE) -> 玩的入迷-魔卡少女樱第一弹—樱之绮遇 | C2: Wamder Roaming Sakura | D2: 12 | E2: =D2*VLOOKUP(A2,Nhập入库!A:N,8,FALSE) -> 156 | G2: Thùy 阿锤 | H2: Dũng 阿勇 | I2: 2025.10.16 | J2: 0.47986111
A3: =VLOOKUP($C3,SKU!$A:$I,3,FALSE) -> 10016 | B3: =VLOOKUP($C3,SKU!$A:$I,2,FALSE) -> 思梨普文创《hey!国王陛下》集换式艺术家典藏卡 | C3: Quàng Thượng | D3: 5 | E3: =D3*VLOOKUP(A3,Nhập入库!A:N,8,FALSE) -> 50 | G3: Thùy 阿锤 | H3: Dũng 阿勇 | I3: 2025.10.16 | J3: 0.47986111
A4: =VLOOKUP($C4,SKU!$A:$I,3,FALSE) -> 10010 | B4: =VLOOKUP($C4,SKU!$A:$I,2,FALSE) -> 玩的入迷-魔卡少女樱第一弹—樱之绮遇 | C4: Wamder Roaming Sakura | D4: 24 | E4: =D4*VLOOKUP(A4,Nhập入库!A:N,8,FALSE) -> 312 | G4: Thùy 阿锤 | H4: Dũng 阿勇 | I4: 2025.10.16 | J4: 0.51736111
A5: =VLOOKUP($C5,SKU!$A:$I,3,FALSE) -> 10015 | B5: =VLOOKUP($C5,SKU!$A:$I,2,FALSE) -> 梦绘文创-宫崎骏第二弹 | C5: MH Gibli | D5: 5 | E5: =D5*VLOOKUP(A5,Nhập入库!A:N,8,FALSE) -> 60 | G5: Thành Đạt 成达 | H5: Dũng 阿勇 | I5: 2025.10.16 | J5: 0.55694444
A6: =VLOOKUP($C6,SKU!$A:$I,3,FALSE) -> 10003 | B6: =VLOOKUP($C6,SKU!$A:$I,2,FALSE) -> DUO米全新出品鬼灭之刃-柱合会议篇第二弹 | C6: DUO Kyn | D6: 5 | E6: =D6*VLOOKUP(A6,Nhập入库!A:N,8,FALSE) -> 65 | G6: Bội Anh 倍英 | H6: Dũng 阿勇 | I6: 2025.10.16 | J6: 0.55694444
A7: =VLOOKUP($C7,SKU!$A:$I,3,FALSE) -> 10020 | B7: =VLOOKUP($C7,SKU!$A:$I,2,FALSE) -> 集卡社小樱 | C7: Sakura Card Fun | D7: 5 | E7: =D7*VLOOKUP(A7,Nhập入库!A:N,8,FALSE) -> 80 | G7: Thùy 阿锤 | H7: Huệ 氏惠 | I7: 45947 | J7: 0.39027778
A8: =VLOOKUP($C8,SKU!$A:$I,3,FALSE) -> 10021 | B8: =VLOOKUP($C8,SKU!$A:$I,2,FALSE) -> 新谷动漫名侦探柯南·仲夏夜之恋邮票集 | C8: Shingu Conan phiếu tem | D8: 10 | E8: =D8*VLOOKUP(A8,Nhập入库!A:N,8,FALSE) -> 50 | G8: Mimi | H8: Trà My 茶梅 | I8: 45948 | J8: 0.40347222
A9: =VLOOKUP($C9,SKU!$A:$I,3,FALSE) -> 10014 | B9: =VLOOKUP($C9,SKU!$A:$I,2,FALSE) -> 星梦文创-Studio Ghibli宫崎骏撕撕乐系列 | C9: Tinh Mộng Gibli thẻ xé | D9: 20 | E9: =D9*VLOOKUP(A9,Nhập入库!A:N,8,FALSE) -> 60 | G9: Hà 小河 | H9: Trà My 茶梅 | I9: 45948 | J9: 0.40347222
A10: =VLOOKUP($C10,SKU!$A:$I,3,FALSE) -> 10028 | B10: =VLOOKUP($C10,SKU!$A:$I,2,FALSE) -> 潮玩咔原神 尘世收藏卡 | C10: Trendy Toyka Genshin | D10: 5 | E10: =D10*VLOOKUP(A10,Nhập入库!A:N,8,FALSE) -> 65 | G10: Bội Anh 倍英 | H10: Dũng 阿勇 | I10: 45948 | J10: 0.45625
A11: =VLOOKUP($C11,SKU!$A:$I,3,FALSE) -> 10018 | B11: =VLOOKUP($C11,SKU!$A:$I,2,FALSE) -> 圣月美少女战士星尘协奏曲长卡 | C11: Sacred Sailor Moon | D11: 5 | E11: =D11*VLOOKUP(A11,Nhập入库!A:N,8,FALSE) -> 65 | G11: Thùy 阿锤 | H11: Huệ 氏惠 | I11: 45948 | J11: 0.41875
A12: =VLOOKUP($C12,SKU!$A:$I,3,FALSE) -> 10028 | B12: =VLOOKUP($C12,SKU!$A:$I,2,FALSE) -> 潮玩咔原神 尘世收藏卡 | C12: Trendy Toyka Genshin | D12: 5 | E12: =D12*VLOOKUP(A12,Nhập入库!A:N,8,FALSE) -> 65 | G12: Bội Anh 倍英 | H12: Dũng 阿勇 | I12: 45948 | J12: 0.55763889
A13: =VLOOKUP($C13,SKU!$A:$I,3,FALSE) -> 10022 | B13: =VLOOKUP($C13,SKU!$A:$I,2,FALSE) -> 【耀光·美少女战士】长卡卡砖 | C13: Sailor Shining | D13: 10 | E13: =D13*VLOOKUP(A13,Nhập入库!A:N,8,FALSE) -> 80 | G13: Thùy 阿锤 | H13: Dũng 阿勇 | I13: 45948 | J13: 0.55763889
A14: =VLOOKUP($C14,SKU!$A:$I,3,FALSE) -> 10021 | B14: =VLOOKUP($C14,SKU!$A:$I,2,FALSE) -> 新谷动漫名侦探柯南·仲夏夜之恋邮票集 | C14: Shingu Conan phiếu tem | D14: 5 | E14: =D14*VLOOKUP(A14,Nhập入库!A:N,8,FALSE) -> 25 | G14: Phương 小芳 | H14: Tum 阿庄 | I14: 45948 | J14: 0.69583333
A15: =VLOOKUP($C15,SKU!$A:$I,3,FALSE) -> 10028 | B15: =VLOOKUP($C15,SKU!$A:$I,2,FALSE) -> 潮玩咔原神 尘世收藏卡 | C15: Trendy Toyka Genshin | D15: 5 | E15: =D15*VLOOKUP(A15,Nhập入库!A:N,8,FALSE) -> 65 | G15: Như 小如 | H15: Tum 阿庄 | I15: 45948 | J15: 0.71736111
A16: =VLOOKUP($C16,SKU!$A:$I,3,FALSE) -> 10021 | B16: =VLOOKUP($C16,SKU!$A:$I,2,FALSE) -> 新谷动漫名侦探柯南·仲夏夜之恋邮票集 | C16: Shingu Conan phiếu tem | D16: 6 | E16: =D16*VLOOKUP(A16,Nhập入库!A:N,8,FALSE) -> 30 | G16: Vi 小薇 | H16: Hoàng Oanh黄莹 | I16: 45948 | J16: 0.75486111
A17: =VLOOKUP($C17,SKU!$A:$I,3,FALSE) -> 10021 | B17: =VLOOKUP($C17,SKU!$A:$I,2,FALSE) -> 新谷动漫名侦探柯南·仲夏夜之恋邮票集 | C17: Shingu Conan phiếu tem | D17: 5 | E17: =D17*VLOOKUP(A17,Nhập入库!A:N,8,FALSE) -> 25 | G17: Mimi | H17: Trà My 茶梅 | I17: 45948 | J17: 0.76111111
A18: =VLOOKUP($C18,SKU!$A:$I,3,FALSE) -> 10013 | B18: =VLOOKUP($C18,SKU!$A:$I,2,FALSE) -> 皇卡 × 鬼灭《血月之契》篇决战无限城收藏卡 | C18: Kny Hoàng Card | D18: 5 | E18: =D18*VLOOKUP(A18,Nhập入库!A:N,8,FALSE) -> 60 | G18: Vi 小薇 | H18: Hoàng Oanh黄莹 | I18: 45948 | J18: 0.94861111
... A48: =VLOOKUP($C48,SKU!$A:$I,3,FALSE) -> 10005 | B48: =VLOOKUP($C48,SKU!$A:$I,2,FALSE) -> 椿柚文创宫崎骏 被风吹散的秘密邮票第一弹 | C48: Gibli Wind | D48: 20 | E48: =D48*VLOOKUP(A48,Nhập入库!A:N,8,FALSE) -> 20 | G48: Zenex | H48: Hoàng 范范 | I48: 45947 | J48: 0.79583333
A49: =VLOOKUP($C49,SKU!$A:$I,3,FALSE) -> 10039 | B49: =VLOOKUP($C49,SKU!$A:$I,2,FALSE) -> 非凡航海王第五弹 | C49: OP Phi Phàm | D49: =48*3 -> 144 | E49: =D49*VLOOKUP(A49,Nhập入库!A:N,8,FALSE) -> 2880 | G49: Zenex | H49: Hoàng 范范 | I49: 45949 | J49: 0.88888889
A50: =VLOOKUP($C50,SKU!$A:$I,3,FALSE) -> 10023 | B50: =VLOOKUP($C50,SKU!$A:$I,2,FALSE) -> 风信文创尘世相逢之约星光来信原神邮票第一弹 | C50: Tinh quang Genshin | D50: 20 | E50: =D50*VLOOKUP(A50,Nhập入库!A:N,8,FALSE) -> 20 | G50: Zenex | H50: Kiều Anh侨英 | I50: 45951 | J50: 0.84236111
A51: =VLOOKUP($C51,SKU!$A:$I,3,FALSE) -> 10013 | B51: =VLOOKUP($C51,SKU!$A:$I,2,FALSE) -> 皇卡 × 鬼灭《血月之契》篇决战无限城收藏卡 | C51: Kny Hoàng Card | D51: 5 | E51: =D51*VLOOKUP(A51,Nhập入库!A:N,8,FALSE) -> 60 | G51: Như 小如 | H51: Tum 阿庄 | I51: 45951 | J51: 0.87916667
A52: =VLOOKUP($C52,SKU!$A:$I,3,FALSE) -> 10013 | B52: =VLOOKUP($C52,SKU!$A:$I,2,FALSE) -> 皇卡 × 鬼灭《血月之契》篇决战无限城收藏卡 | C52: Kny Hoàng Card | D52: 5 | E52: =D52*VLOOKUP(A52,Nhập入库!A:N,8,FALSE) -> 60 | G52: Như 小如 | H52: Tum 阿庄 | I52: 45951 | J52: 0.9
A53: =VLOOKUP($C53,SKU!$A:$I,3,FALSE) -> 10023 | B53: =VLOOKUP($C53,SKU!$A:$I,2,FALSE) -> 风信文创尘世相逢之约星光来信原神邮票第一弹 | C53: Tinh quang Genshin | D53: 40 | E53: =D53*VLOOKUP(A53,Nhập入库!A:N,8,FALSE) -> 40 | G53: Bội Anh 倍英 | H53: Dũng 阿勇 | I53: 2025.10.22 | J53: 0.39027778
A54: =VLOOKUP($C54,SKU!$A:$I,3,FALSE) -> 10017 | B54: =VLOOKUP($C54,SKU!$A:$I,2,FALSE) -> 梦境-美少女战士第一弹 | C54: Mộng cảnh Sailor Moon | D54: 5 | E54: =D54*VLOOKUP(A54,Nhập入库!A:N,8,FALSE) -> 65 | G54: Thùy 阿锤 | H54: Dũng 阿勇 | I54: 2025.10.16 | J54: 0.68888889
A55: =VLOOKUP($C55,SKU!$A:$I,3,FALSE) -> 10017 | B55: =VLOOKUP($C55,SKU!$A:$I,2,FALSE) -> 梦境-美少女战士第一弹 | C55: Mộng cảnh Sailor Moon | D55: 5 | E55: =D55*VLOOKUP(A55,Nhập入库!A:N,8,FALSE) -> 65 | G55: Thùy 阿锤 | H55: Dũng 阿勇 | I55: 45947 | J55: 0.43888889
A56: =VLOOKUP($C56,SKU!$A:$I,3,FALSE) -> 10035 | B56: =VLOOKUP($C56,SKU!$A:$I,2,FALSE) -> KK CARD × 新海诚系列第一弹 | C56: KK card Shinkai Makoto vol 1 | D56: 5 | E56: =D56*VLOOKUP(A56,Nhập入库!A:N,8,FALSE) -> 70 | G56: Thùy 阿锤 | H56: Dũng 阿勇 | I56: 45947 | J56: 0.85555556
A57: =VLOOKUP($C57,SKU!$A:$I,3,FALSE) -> 10026 | B57: =VLOOKUP($C57,SKU!$A:$I,2,FALSE) -> 星恋文创·恋与深空《晦明交错之间》亚克力相框卡 | C57: Hải Minh LnD | D57: 100 | E57: =D57*VLOOKUP(A57,Nhập入库!A:N,8,FALSE) -> 100 | G57: Thành Đạt 成达 | H57: Dũng 阿勇 | I57: 45947 | J57: 0.89722222
A58: =VLOOKUP($C58,SKU!$A:$I,3,FALSE) -> 10011 | B58: =VLOOKUP($C58,SKU!$A:$I,2,FALSE) -> 灿卡文创宫崎骏第二弹《花涧物语》 | C58: Gibli Hoa | D58: 15 | E58: =D58*VLOOKUP(A58,Nhập入库!A:N,8,FALSE) -> 195 | G58: Thanh 阿青 | H58: Hoàng Oanh黄莹 | I58: 2025.10.16 | J58: 0.83194444
A59: =VLOOKUP($C59,SKU!$A:$I,3,FALSE) -> 10044 | B59: =VLOOKUP($C59,SKU!$A:$I,2,FALSE) -> 源宇宙原神.空月の歌·周边CD票根邮票组合套装 | C59: Source University Genshin thẻ CD | D59: 20 | E59: =D59*VLOOKUP(A59,Nhập入库!A:N,8,FALSE) -> 20 | G59: Bội Anh 倍英 | H59: Dũng 阿勇 | I59: 2025.10.22 | J59: 0.54722222
A60: =VLOOKUP($C60,SKU!$A:$I,3,FALSE) -> 10011 | B60: =VLOOKUP($C60,SKU!$A:$I,2,FALSE) -> 灿卡文创宫崎骏第二弹《花涧物语》 | C60: Gibli Hoa | D60: 5 | E60: =D60*VLOOKUP(A60,Nhập入库!A:N,8,FALSE) -> 65 | G60: Thành Đạt 成达 | H60: Dũng 阿勇 | I60: 2025.10.22 | J60: 0.47638889
A61: =VLOOKUP($C61,SKU!$A:$I,3,FALSE) -> 10031 | B61: =VLOOKUP($C61,SKU!$A:$I,2,FALSE) -> 胜卡文创x魔道祖师云深不忘邮票评级卡砖 | C61: SK MĐTS phiếu tem | D61: 5 | E61: =D61*VLOOKUP(A61,Nhập入库!A:N,8,FALSE) -> 50 | G61: Thùy 阿锤 | H61: Dũng 阿勇 | I61: 2025.10.22 | J61: 0.48194444
A62: =VLOOKUP($C62,SKU!$A:$I,3,FALSE) -> 10031 | B62: =VLOOKUP($C62,SKU!$A:$I,2,FALSE) -> 胜卡文创x魔道祖师云深不忘邮票评级卡砖 | C62: SK MĐTS phiếu tem | D62: 2 | E62: =D62*VLOOKUP(A62,Nhập入库!A:N,8,FALSE) -> 20 | G62: Thùy 阿锤 | H62: Dũng 阿勇 | I62: 2025.10.22 | J62: 0.56527778
A63: =VLOOKUP($C63,SKU!$A:$I,3,FALSE) -> 10031 | B63: =VLOOKUP($C63,SKU!$A:$I,2,FALSE) -> 胜卡文创x魔道祖师云深不忘邮票评级卡砖 | C63: SK MĐTS phiếu tem | D63: 12 | E63: =D63*VLOOKUP(A63,Nhập入库!A:N,8,FALSE) -> 120 | G63: Thùy 阿锤 | H63: Dũng 阿勇 | I63: 2025.10.22 | J63: 0.60138889
A64: =VLOOKUP($C64,SKU!$A:$I,3,FALSE) -> 10006 | B64: =VLOOKUP($C64,SKU!$A:$I,2,FALSE) -> 云映文化「云之境の夏」第二弹·宫崎骏珍藏卡牌 | C64: Mây và Hạ | D64: 5 | E64: =D64*VLOOKUP(A64,Nhập入库!A:N,8,FALSE) -> 65 | G64: Hà 小河 | H64: Trà My 茶梅 | I64: 2025.10.22 | J64: 0.57986111
A65: =VLOOKUP($C65,SKU!$A:$I,3,FALSE) -> 10007 | B65: =VLOOKUP($C65,SKU!$A:$I,2,FALSE) -> kawaii宫崎骏梦幻之国 | C65: Kawaii Gibli | D65: 10 | E65: =D65*VLOOKUP(A65,Nhập入库!A:N,8,FALSE) -> 130 | G65: Mimi | H65: Trà My 茶梅 | I65: 2025.10.22 | J65: 0.60138889
A66: =VLOOKUP($C66,SKU!$A:$I,3,FALSE) -> 10017 | B66: =VLOOKUP($C66,SKU!$A:$I,2,FALSE) -> 梦境-美少女战士第一弹 | C66: Mộng cảnh Sailor Moon | D66: 5 | E66: =D66*VLOOKUP(A66,Nhập入库!A:N,8,FALSE) -> 65 | G66: Vi 小薇 | H66: Hoàng Oanh黄莹 | I66: 45949 | J66: 0.91875
A67: =VLOOKUP($C67,SKU!$A:$I,3,FALSE) -> 10012 | B67: =VLOOKUP($C67,SKU!$A:$I,2,FALSE) -> 卡文化进击的巨人 | C67: Attack on Titan | D67: 5 | E67: =D67*VLOOKUP(A67,Nhập入库!A:N,8,FALSE) -> 150 | G67: Như 小如 | H67: Tum 阿庄 | I67: 2025.10.22 | J67: 0.81458333
A68: =VLOOKUP($C68,SKU!$A:$I,3,FALSE) -> 10003 | B68: =VLOOKUP($C68,SKU!$A:$I,2,FALSE) -> DUO米全新出品鬼灭之刃-柱合会议篇第二弹 | C68: DUO Kyn | D68: 5 | E68: =D68*VLOOKUP(A68,Nhập入库!A:N,8,FALSE) -> 65 | G68: Như 小如 | H68: Tum 阿庄 | I68: 2025.10.22 | J68: 0.81597222
A69: =VLOOKUP($C69,SKU!$A:$I,3,FALSE) -> 10006 | B69: =VLOOKUP($C69,SKU!$A:$I,2,FALSE) -> 云映文化「云之境の夏」第二弹·宫崎骏珍藏卡牌 | C69: Mây và Hạ | D69: 5 | E69: =D69*VLOOKUP(A69,Nhập入库!A:N,8,FALSE) -> 65 | G69: Phương 小芳 | H69: Tum 阿庄 | I69: 2025.10.22 | J69: 0.96180556
...

Sheet Hoàn回库
A1: sku序列 SKU CODE | B1: 中文名 Tên tiếng Trung | C1: 英文/越文名 Tên tiếng Việt | D1: 数量/盒 SL hộp | E1: 整盒包数 SL (Pack/Tổng Hộp) | F1: 零散包数 Pack lẻ | G1: 主播 Từ Host | H1: 登记人 Người hoàn | I1: 回库日期 Ngày hoàn | J1: 回库时间 Thời gian
A2: =VLOOKUP($C2,SKU!$A:$I,3,FALSE) -> 10013 | B2: =VLOOKUP($C2,SKU!$A:$I,2,FALSE) -> 皇卡 × 鬼灭《血月之契》篇决战无限城收藏卡 | C2: Kny Hoàng Card | E2: =D2*VLOOKUP(A2,Nhập入库!A:N,8,FALSE) -> 0 | F2: 36 | G2: Vi 小薇 | H2: Tum 阿庄 | I2: 23/10/2025 | J2: 0.78333333
A3: =VLOOKUP($C3,SKU!$A:$I,3,FALSE) -> 10013 | B3: =VLOOKUP($C3,SKU!$A:$I,2,FALSE) -> 皇卡 × 鬼灭《血月之契》篇决战无限城收藏卡 | C3: Kny Hoàng Card | D3: 3 | E3: =D3*VLOOKUP(A3,Nhập入库!A:N,8,FALSE) -> 36 | F3: 44 | G3: Vi 小薇 | H3: Huệ 氏惠 | I3: 24/10/2025 | J3: 0.41666667
A4: =VLOOKUP($C4,SKU!$A:$I,3,FALSE) -> 10039 | B4: =VLOOKUP($C4,SKU!$A:$I,2,FALSE) -> 非凡航海王第五弹 | C4: OP Phi Phàm | D4: 5 | E4: =D4*VLOOKUP(A4,Nhập入库!A:N,8,FALSE) -> 100 | F4: 21 | G4: Zenex | H4: Trà My 茶梅 | I4: 23/10/2025 | J4: 0.37222222
A5: =VLOOKUP($C5,SKU!$A:$I,3,FALSE) -> 10003 | B5: =VLOOKUP($C5,SKU!$A:$I,2,FALSE) -> DUO米全新出品鬼灭之刃-柱合会议篇第二弹 | C5: DUO Kyn | D5: 5 | E5: =D5*VLOOKUP(A5,Nhập入库!A:N,8,FALSE) -> 65 | G5: Thu Giang秋江 | H5: Hoàng Oanh黄莹 | I5: 24/10/2025 | J5: 0.88888889
A6: =VLOOKUP($C6,SKU!$A:$I,3,FALSE) -> 10003 | B6: =VLOOKUP($C6,SKU!$A:$I,2,FALSE) -> DUO米全新出品鬼灭之刃-柱合会议篇第二弹 | C6: DUO Kyn | D6: 5 | E6: =D6*VLOOKUP(A6,Nhập入库!A:N,8,FALSE) -> 65 | G6: Hà 小河 | H6: Tum 阿庄 | I6: 25/10/2025 | J6: 0.95486111
A7: =VLOOKUP($C7,SKU!$A:$I,3,FALSE) -> 10003 | B7: =VLOOKUP($C7,SKU!$A:$I,2,FALSE) -> DUO米全新出品鬼灭之刃-柱合会议篇第二弹 | C7: DUO Kyn | D7: 1 | E7: =D7*VLOOKUP(A7,Nhập入库!A:N,8,FALSE) -> 13 | F7: 13 | G7: Vi 小薇 | H7: Trà My 茶梅 | I7: 25/10/2025 | J7: 0.63611111
A8: =VLOOKUP($C8,SKU!$A:$I,3,FALSE) -> 10021 | B8: =VLOOKUP($C8,SKU!$A:$I,2,FALSE) -> 新谷动漫名侦探柯南·仲夏夜之恋邮票集 | C8: Shingu Conan phiếu tem | D8: 4 | E8: =D8*VLOOKUP(A8,Nhập入库!A:N,8,FALSE) -> 20 | G8: Mimi | H8: Tum 阿庄 | I8: 26/10/2025 | J8: 0.73055556
A9: =VLOOKUP($C9,SKU!$A:$I,3,FALSE) -> 10003 | B9: =VLOOKUP($C9,SKU!$A:$I,2,FALSE) -> DUO米全新出品鬼灭之刃-柱合会议篇第二弹 | C9: DUO Kyn | D9: 4 | E9: =D9*VLOOKUP(A9,Nhập入库!A:N,8,FALSE) -> 52 | G9: Thu Giang秋江 | H9: Hoàng Oanh黄莹 | I9: 26/10/2025 | J9: 0.81597222
A10: =VLOOKUP($C10,SKU!$A:$I,3,FALSE) -> 10003 | B10: =VLOOKUP($C10,SKU!$A:$I,2,FALSE) -> DUO米全新出品鬼灭之刃-柱合会议篇第二弹 | C10: DUO Kyn | E10: =D10*VLOOKUP(A10,Nhập入库!A:N,8,FALSE) -> 0 | F10: 85 | G10: Mimi | H10: Tum 阿庄 | I10: 26/10/2026 | J10: 0.78263889
A11: =VLOOKUP($C11,SKU!$A:$I,3,FALSE) -> 10010 | B11: =VLOOKUP($C11,SKU!$A:$I,2,FALSE) -> 玩的入迷-魔卡少女樱第一弹—樱之绮遇 | C11: Wamder Roaming Sakura | D11: 5 | E11: =D11*VLOOKUP(A11,Nhập入库!A:N,8,FALSE) -> 65 | F11: 24 | G11: Thùy 阿锤 | H11: Hoàng Oanh黄莹 | I11: 26/10/2026 | J11: 0.97430556
A12: =VLOOKUP($C12,SKU!$A:$I,3,FALSE) -> 10003 | B12: =VLOOKUP($C12,SKU!$A:$I,2,FALSE) -> DUO米全新出品鬼灭之刃-柱合会议篇第二弹 | C12: DUO Kyn | D12: 1 | E12: =D12*VLOOKUP(A12,Nhập入库!A:N,8,FALSE) -> 13 | F12: 13 | G12: Như 小如 | H12: Trà My 茶梅 | I12: 25/10/2026 | J12: 0.375
A13: =VLOOKUP($C13,SKU!$A:$I,3,FALSE) -> 10003 | B13: =VLOOKUP($C13,SKU!$A:$I,2,FALSE) -> DUO米全新出品鬼灭之刃-柱合会议篇第二弹 | C13: DUO Kyn | D13: 1 | E13: =D13*VLOOKUP(A13,Nhập入库!A:N,8,FALSE) -> 13 | F13: 13 | G13: Vi 小薇 | H13: Trà My 茶梅 | I13: 25/10/2025 | J13: 0.375
A14: =VLOOKUP($C14,SKU!$A:$I,3,FALSE) -> 10044 | B14: =VLOOKUP($C14,SKU!$A:$I,2,FALSE) -> 源宇宙原神.空月の歌·周边CD票根邮票组合套装 | C14: Source University Genshin thẻ CD | D14: 1 | E14: =D14*VLOOKUP(A14,Nhập入库!A:N,8,FALSE) -> 1 | G14: Bội Anh 倍英 | H14: Trà My 茶梅 | I14: 27/10/2025 | J14: 0.375
A15: =VLOOKUP($C15,SKU!$A:$I,3,FALSE) -> 10003 | B15: =VLOOKUP($C15,SKU!$A:$I,2,FALSE) -> DUO米全新出品鬼灭之刃-柱合会议篇第二弹 | C15: DUO Kyn | E15: =D15*VLOOKUP(A15,Nhập入库!A:N,8,FALSE) -> 0 | F15: 17 | G15: Mimi | H15: Trà My 茶梅 | I15: 28/10/2025 | J15: 0.56319444
A16: =VLOOKUP($C16,SKU!$A:$I,3,FALSE) -> 10003 | B16: =VLOOKUP($C16,SKU!$A:$I,2,FALSE) -> DUO米全新出品鬼灭之刃-柱合会议篇第二弹 | C16: DUO Kyn | E16: =D16*VLOOKUP(A16,Nhập入库!A:N,8,FALSE) -> 0 | F16: 15 | G16: Như 小如 | H16: Trà My 茶梅 | I16: 28/10/2025 | J16: 0.58333333
A17: =VLOOKUP($C17,SKU!$A:$I,3,FALSE) -> 10003 | B17: =VLOOKUP($C17,SKU!$A:$I,2,FALSE) -> DUO米全新出品鬼灭之刃-柱合会议篇第二弹 | C17: DUO Kyn | D17: 1 | E17: =D17*VLOOKUP(A17,Nhập入库!A:N,8,FALSE) -> 13 | G17: Như 小如 | H17: Hoàng Oanh黄莹 | I17: 28/10/2025 | J17: 0.34722222
A18: =VLOOKUP($C18,SKU!$A:$I,3,FALSE) -> 10021 | B18: =VLOOKUP($C18,SKU!$A:$I,2,FALSE) -> 新谷动漫名侦探柯南·仲夏夜之恋邮票集 | C18: Shingu Conan phiếu tem | E18: =D18*VLOOKUP(A18,Nhập入库!A:N,8,FALSE) -> 0 | F18: 1 | G18: Mimi | H18: Hoàng Oanh黄莹 | I18: 28/10/2025 | J18: 0.99097222
A19: =VLOOKUP($C19,SKU!$A:$I,3,FALSE) -> 10003 | B19: =VLOOKUP($C19,SKU!$A:$I,2,FALSE) -> DUO米全新出品鬼灭之刃-柱合会议篇第二弹 | C19: DUO Kyn | D19: 1 | E19: =D19*VLOOKUP(A19,Nhập入库!A:N,8,FALSE) -> 13 | F19: 13 | G19: Vi 小薇 | H19: Hoàng Oanh黄莹 | I19: 28/10/2025 | J19: 0.99097222
A20: =VLOOKUP($C20,SKU!$A:$I,3,FALSE) -> 10003 | B20: =VLOOKUP($C20,SKU!$A:$I,2,FALSE) -> DUO米全新出品鬼灭之刃-柱合会议篇第二弹 | C20: DUO Kyn | E20: =D20*VLOOKUP(A20,Nhập入库!A:N,8,FALSE) -> 0 | F20: 13 | G20: Vi 小薇 | H20: Trà My 茶梅 | I20: 28/10/2025 | J20: 0.54166667
A21: =VLOOKUP($C21,SKU!$A:$I,3,FALSE) -> 10003 | B21: =VLOOKUP($C21,SKU!$A:$I,2,FALSE) -> DUO米全新出品鬼灭之刃-柱合会议篇第二弹 | C21: DUO Kyn | E21: =D21*VLOOKUP(A21,Nhập入库!A:N,8,FALSE) -> 0 | F21: 36 | G21: Bội Anh 倍英 | H21: Kiều Anh侨英 | I21: 29/10/2025 | J21: 0.77708333
A22: =VLOOKUP($C22,SKU!$A:$I,3,FALSE) -> 10044 | B22: =VLOOKUP($C22,SKU!$A:$I,2,FALSE) -> 源宇宙原神.空月の歌·周边CD票根邮票组合套装 | C22: Source University Genshin thẻ CD | E22: =D22*VLOOKUP(A22,Nhập入库!A:N,8,FALSE) -> 0 | F22: 7 | G22: Như 小如 | H22: Dũng 阿勇 | I22: 28/10/2025 | J22: 0.54166667
A23: =VLOOKUP($C23,SKU!$A:$I,3,FALSE) -> 10001 | B23: =VLOOKUP($C23,SKU!$A:$I,2,FALSE) -> 《东株社》宝可梦水晶砖 | C23: Pokemon | E23: =D23*VLOOKUP(A23,Nhập入库!A:N,8,FALSE) -> 0 | F23: 3 | G23: Bội Anh 倍英 | H23: Dũng 阿勇 | I23: 28/10/2025 | J23: 0.54166667
A24: =VLOOKUP($C24,SKU!$A:$I,3,FALSE) -> 10004 | B24: =VLOOKUP($C24,SKU!$A:$I,2,FALSE) -> 初见花海咒术回战第一弹 | C24: Jujutsu vol 1 | E24: =D24*VLOOKUP(A24,Nhập入库!A:N,8,FALSE) -> 0 | F24: 15 | G24: Mimi | H24: Dũng 阿勇 | I24: 1/11/2025 | J24: 0.39166667
A25: =VLOOKUP($C25,SKU!$A:$I,3,FALSE) -> 10010 | B25: =VLOOKUP($C25,SKU!$A:$I,2,FALSE) -> 玩的入迷-魔卡少女樱第一弹—樱之绮遇 | C25: Wamder Roaming Sakura | E25: =D25*VLOOKUP(A25,Nhập入库!A:N,8,FALSE) -> 0 | F25: 23 | G25: Thanh 阿青 | H25: Dũng 阿勇 | I25: 31/10/2025 | J25: 0.42569444
A26: =VLOOKUP($C26,SKU!$A:$I,3,FALSE) -> 10037 | B26: =VLOOKUP($C26,SKU!$A:$I,2,FALSE) -> 磁吸邮票《咪咕咪咕&魔卡少女樱》 | C26: Madhouse Sakura phiếu tem | D26: 20 | E26: =D26*VLOOKUP(A26,Nhập入库!A:N,8,FALSE) -> 20 | G26: Thùy 阿锤 | H26: Dũng 阿勇 | I26: 31/10/2025
A27: =VLOOKUP($C27,SKU!$A:$I,3,FALSE) -> 10025 | B27: =VLOOKUP($C27,SKU!$A:$I,2,FALSE) -> 君屹文化耽美古风收藏新纪元《言辞忆梦》撕撕乐 | C27: Quân sơn TQTP | E27: =D27*VLOOKUP(A27,Nhập入库!A:N,8,FALSE) -> 0 | F27: 18 | G27: Thanh 阿青 | H27: Hoàng Oanh黄莹 | I27: 31/10/2025 | J27: 0.70833333
A28: =VLOOKUP($C28,SKU!$A:$I,3,FALSE) -> 10017 | B28: =VLOOKUP($C28,SKU!$A:$I,2,FALSE) -> 梦境-美少女战士第一弹 | C28: Mộng cảnh Sailor Moon | D28: 2 | E28: =D28*VLOOKUP(A28,Nhập入库!A:N,8,FALSE) -> 26 | G28: Hà 小河 | H28: Dũng 阿勇 | I28: 1/11/2025 | J28: 0.62222222
A29: =VLOOKUP($C29,SKU!$A:$I,3,FALSE) -> 10013 | B29: =VLOOKUP($C29,SKU!$A:$I,2,FALSE) -> 皇卡 × 鬼灭《血月之契》篇决战无限城收藏卡 | C29: Kny Hoàng Card | D29: 3 | E29: =D29*VLOOKUP(A29,Nhập入库!A:N,8,FALSE) -> 36 | G29: Thu Giang秋江 | H29: Kiều Anh侨英 | I29: 1/11/2025 | J29: 0.73055556
A30: =VLOOKUP($C30,SKU!$A:$I,3,FALSE) -> 10003 | B30: =VLOOKUP($C30,SKU!$A:$I,2,FALSE) -> DUO米全新出品鬼灭之刃-柱合会议篇第二弹 | C30: DUO Kyn | D30: 3 | E30: =D30*VLOOKUP(A30,Nhập入库!A:N,8,FALSE) -> 39 | G30: Hà 小河 | H30: Hoàng Oanh黄莹 | I30: 1/11/2025 | J30: 0.82361111
A31: =VLOOKUP($C31,SKU!$A:$I,3,FALSE) -> 10003 | B31: =VLOOKUP($C31,SKU!$A:$I,2,FALSE) -> DUO米全新出品鬼灭之刃-柱合会议篇第二弹 | C31: DUO Kyn | E31: =D31*VLOOKUP(A31,Nhập入库!A:N,8,FALSE) -> 0 | F31: 20 | G31: Thu Giang秋江 | H31: Hoàng Oanh黄莹 | I31: 1/11/2025 | J31: 0.89027778
A32: =VLOOKUP($C32,SKU!$A:$I,3,FALSE) -> 10003 | B32: =VLOOKUP($C32,SKU!$A:$I,2,FALSE) -> DUO米全新出品鬼灭之刃-柱合会议篇第二弹 | C32: DUO Kyn | E32: =D32*VLOOKUP(A32,Nhập入库!A:N,8,FALSE) -> 0 | F32: 12 | G32: Hà 小河 | H32: Hoàng Oanh黄莹 | I32: 1/11/2025 | J32: 0.91111111
A33: =VLOOKUP($C33,SKU!$A:$I,3,FALSE) -> 10003 | B33: =VLOOKUP($C33,SKU!$A:$I,2,FALSE) -> DUO米全新出品鬼灭之刃-柱合会议篇第二弹 | C33: DUO Kyn | E33: =D33*VLOOKUP(A33,Nhập入库!A:N,8,FALSE) -> 0 | F33: =30+28 -> 58 | G33: Hà 小河 | H33: Hoàng Oanh黄莹 | I33: 1/11/2025 | J33: 0.9625
A34: =VLOOKUP($C34,SKU!$A:$I,3,FALSE) -> 10003 | B34: =VLOOKUP($C34,SKU!$A:$I,2,FALSE) -> DUO米全新出品鬼灭之刃-柱合会议篇第二弹 | C34: DUO Kyn | E34: =D34*VLOOKUP(A34,Nhập入库!A:N,8,FALSE) -> 0 | F34: 49 | G34: Vi 小薇 | H34: Tum 阿庄 | I34: 1/11/2025 | J34: 0.99097222
A35: =VLOOKUP($C35,SKU!$A:$I,3,FALSE) -> 10037 | B35: =VLOOKUP($C35,SKU!$A:$I,2,FALSE) -> 磁吸邮票《咪咕咪咕&魔卡少女樱》 | C35: Madhouse Sakura phiếu tem | D35: 20 | E35: =D35*VLOOKUP(A35,Nhập入库!A:N,8,FALSE) -> 20 | G35: Thùy 阿锤 | H35: Dũng 阿勇 | I35: 2/11/2025 | J35: 0.49097222
A36: =VLOOKUP($C36,SKU!$A:$I,3,FALSE) -> 10035 | B36: =VLOOKUP($C36,SKU!$A:$I,2,FALSE) -> KK CARD × 新海诚系列第一弹 | C36: KK card Shinkai Makoto vol 1 | E36: =D36*VLOOKUP(A36,Nhập入库!A:N,8,FALSE) -> 0 | F36: 41 | G36: Thùy 阿锤 | H36: Dũng 阿勇 | I36: 2/11/2025 | J36: 0.59513889
A37: =VLOOKUP($C37,SKU!$A:$I,3,FALSE) -> 10004 | B37: =VLOOKUP($C37,SKU!$A:$I,2,FALSE) -> 初见花海咒术回战第一弹 | C37: Jujutsu vol 1 | D37: 22 | E37: =D37*VLOOKUP(A37,Nhập入库!A:N,8,FALSE) -> 22 | G37: Khoa 科 | H37: Huệ 氏惠 | I37: 02/11/2025 | J37: 0.096527778
A38: =VLOOKUP($C38,SKU!$A:$I,3,FALSE) -> 10039 | B38: =VLOOKUP($C38,SKU!$A:$I,2,FALSE) -> 非凡航海王第五弹 | C38: OP Phi Phàm | D38: 5 | E38: =D38*VLOOKUP(A38,Nhập入库!A:N,8,FALSE) -> 100 | G38: Khoa 科 | H38: Huệ 氏惠 | I38: 02/11/2025 | J38: 0.096527778
A39: =VLOOKUP($C39,SKU!$A:$I,3,FALSE) -> 10014 | B39: =VLOOKUP($C39,SKU!$A:$I,2,FALSE) -> 星梦文创-Studio Ghibli宫崎骏撕撕乐系列 | C39: Tinh Mộng Gibli thẻ xé | D39: 20 | E39: =D39*VLOOKUP(A39,Nhập入库!A:N,8,FALSE) -> 60 | G39: Khoa 科 | H39: Huệ 氏惠 | I39: 02/11/2025 | J39: 0.096527778
A40: =VLOOKUP($C40,SKU!$A:$I,3,FALSE) -> 10017 | B40: =VLOOKUP($C40,SKU!$A:$I,2,FALSE) -> 梦境-美少女战士第一弹 | C40: Mộng cảnh Sailor Moon | E40: =D40*VLOOKUP(A40,Nhập入库!A:N,8,FALSE) -> 0 | F40: 29 | G40: Hà 小河 | H40: Huệ 氏惠 | I40: 1/11/2025 | J40: 0.63125
...

Sheet Điều hàng调货
A1: sku序列 SKU CODE | B1: 中文名 Tên tiếng Trung | C1: 英文/越文名 Tên tiếng Việt | D1: 数量/盒 SL hộp | E1: 整盒包数 SL (Pack/Tổng Hộp) | F1: 零散包数 Pack lẻ | G1: 从主播 Từ Host | H1: 到主播 Tới Host | I1: 登记人 Người điều | J1: 调货日期 Ngày điều | K1: 调货时间 Thời gian điều
A2: =VLOOKUP($C2,SKU!$A:$I,3,FALSE) -> 10003 | B2: =VLOOKUP($C2,SKU!$A:$I,2,FALSE) -> DUO米全新出品鬼灭之刃-柱合会议篇第二弹 | C2: DUO Kyn | D2: 0 | E2: =D2*VLOOKUP(A2,Nhập入库!A:N,8,FALSE) -> 0 | F2: 27 | G2: Hà 小河 | H2: Bội Anh 倍英
A3: =VLOOKUP($C3,SKU!$A:$I,3,FALSE) -> 10039 | B3: =VLOOKUP($C3,SKU!$A:$I,2,FALSE) -> 非凡航海王第五弹 | C3: OP Phi Phàm | D3: 0 | E3: =D3*VLOOKUP(A3,Nhập入库!A:N,8,FALSE) -> 0 | F3: 80 | G3: Trường Giang 长江 | H3: Thanh Hằng 青姮 | I3: Hoàng Oanh黄莹 | J3: 6/12/2025 | K3: 0.73819444
A4: =VLOOKUP($C4,SKU!$A:$I,3,FALSE) -> 10057 | B4: =VLOOKUP($C4,SKU!$A:$I,2,FALSE) -> 三丽鸥家族暖冬 | C4: Kabao Sanrio Gia tộc mùa đông ấm áp | D4: 0 | E4: =D4*VLOOKUP(A4,Nhập入库!A:N,8,FALSE) -> 0 | F4: 8 | G4: Bảo Ngọc 宝玉 | H4: Mỹ Nhàn 美嫻 | I4: Tum 阿庄 | J4: 6/12/2025 | K4: 0.88541667
A5: =VLOOKUP($C5,SKU!$A:$I,3,FALSE) -> 10039 | B5: =VLOOKUP($C5,SKU!$A:$I,2,FALSE) -> 非凡航海王第五弹 | C5: OP Phi Phàm | D5: 0 | E5: =D5*VLOOKUP(A5,Nhập入库!A:N,8,FALSE) -> 0 | F5: 22 | G5: Thanh Hằng 青姮 | H5: Test Live | I5: Hoàng Oanh黄莹 | J5: 6/12/2025 | K5: 0.73819444
A6: =VLOOKUP($C6,SKU!$A:$I,3,FALSE) -> 10039 | B6: =VLOOKUP($C6,SKU!$A:$I,2,FALSE) -> 非凡航海王第五弹 | C6: OP Phi Phàm | D6: 1 | E6: =D6*VLOOKUP(A6,Nhập入库!A:N,8,FALSE) -> 20 | G6: Thanh Hằng 青姮 | H6: Uyên Mai 媛梅 | I6: Xuân Nhi 春妮 | J6: 9/12/2025 | K6: 0.38194444
A7: =VLOOKUP($C7,SKU!$A:$I,3,FALSE) -> 10057 | B7: =VLOOKUP($C7,SKU!$A:$I,2,FALSE) -> 三丽鸥家族暖冬 | C7: Kabao Sanrio Gia tộc mùa đông ấm áp | D7: 1 | E7: =D7*VLOOKUP(A7,Nhập入库!A:N,8,FALSE) -> 10 | G7: Bảo Ngọc 宝玉 | H7: Thùy 阿锤 | I7: Xuân Nhi 春妮 | J7: 9/12/2025 | K7: 0.39791667
A8: =VLOOKUP($C8,SKU!$A:$I,3,FALSE) -> 10072 | B8: =VLOOKUP($C8,SKU!$A:$I,2,FALSE) -> 伴飞小鸟 | C8: Mô hình chim đồ chơi trang trí xe | D8: 2 | E8: =D8*VLOOKUP(A8,Nhập入库!A:N,8,FALSE) -> 2 | G8: Thùy 阿锤 | H8: Thành Đạt 成达 | I8: Xuân Nhi 春妮 | J8: 9/12/2025 | K8: 0.50555556
A9: =VLOOKUP($C9,SKU!$A:$I,3,FALSE) -> 10046 | B9: =VLOOKUP($C9,SKU!$A:$I,2,FALSE) -> 夜灯 | C9: Đèn Gibli DIY | D9: 3 | E9: =D9*VLOOKUP(A9,Nhập入库!A:N,8,FALSE) -> 3 | G9: Thùy 阿锤 | H9: Thành Đạt 成达 | I9: Xuân Nhi 春妮 | J9: 9/12/2025 | K9: 0.50555556
A10: =VLOOKUP($C10,SKU!$A:$I,3,FALSE) -> 10039 | B10: =VLOOKUP($C10,SKU!$A:$I,2,FALSE) -> 非凡航海王第五弹 | C10: OP Phi Phàm | D10: 1 | E10: =D10*VLOOKUP(A10,Nhập入库!A:N,8,FALSE) -> 20 | G10: Cẩm Giang 锦江 | H10: Thái Châu 泰珠 | I10: Hoàng 范范 | J10: 9/12/2025 | K10: 0.54166667
A11: =VLOOKUP($C11,SKU!$A:$I,3,FALSE) -> 10039 | B11: =VLOOKUP($C11,SKU!$A:$I,2,FALSE) -> 非凡航海王第五弹 | C11: OP Phi Phàm | D11: 1 | E11: =D11*VLOOKUP(A11,Nhập入库!A:N,8,FALSE) -> 20 | G11: Hoàng Anh黄英 | H11: Thành Đạt 成达 | I11: Xuân Nhi 春妮 | J11: 10/12/2025 | K11: 0.66736111
A12: =VLOOKUP($C12,SKU!$A:$I,3,FALSE) -> 10038 | B12: =VLOOKUP($C12,SKU!$A:$I,2,FALSE) -> 浮光工作室❤第三弹【夏风吻过你的睫毛】 | C12: LnD Gió hạ từng hôn mi em | D12: 0 | E12: =D12*VLOOKUP(A12,Nhập入库!A:N,8,FALSE) -> 0 | F12: 16 | G12: Thanh 阿青 | H12: Phương Thảo 芳草 | I12: Hoàng Oanh黄莹 | J12: 10/12/2025 | K12: 0.875
A13: =VLOOKUP($C13,SKU!$A:$I,3,FALSE) -> 10039 | B13: =VLOOKUP($C13,SKU!$A:$I,2,FALSE) -> 非凡航海王第五弹 | C13: OP Phi Phàm | D13: 0 | E13: =D13*VLOOKUP(A13,Nhập入库!A:N,8,FALSE) -> 0 | F13: 322 | G13: Bảo Ngọc 宝玉 | H13: Kiều Phượng 桥凤 | I13: Tum 阿庄 | J13: 10/12/2025 | K13: 0.95833333
A14: =VLOOKUP($C14,SKU!$A:$I,3,FALSE) -> 10039 | B14: =VLOOKUP($C14,SKU!$A:$I,2,FALSE) -> 非凡航海王第五弹 | C14: OP Phi Phàm | D14: 0 | E14: =D14*VLOOKUP(A14,Nhập入库!A:N,8,FALSE) -> 0 | F14: 111 | G14: Hà 小河 | H14: Như 小如 | I14: Tum 阿庄 | J14: 10/12/2025 | K14: 0.99236111
A15: =VLOOKUP($C15,SKU!$A:$I,3,FALSE) -> 10002 | B15: =VLOOKUP($C15,SKU!$A:$I,2,FALSE) -> MoonCard月卡《美少女战士》第三弹 | C15: Moon Card Sailor Moon | D15: 0 | E15: =D15*VLOOKUP(A15,Nhập入库!A:N,8,FALSE) -> 0 | F15: 49 | G15: Phước 小福 | H15: Minh Thư 明书 | I15: Tuyền 绚 | J15: 11/12/2025 | K15: 0.175
A16: =VLOOKUP($C16,SKU!$A:$I,3,FALSE) -> 10057 | B16: =VLOOKUP($C16,SKU!$A:$I,2,FALSE) -> 三丽鸥家族暖冬 | C16: Kabao Sanrio Gia tộc mùa đông ấm áp | D16: 0 | E16: =D16*VLOOKUP(A16,Nhập入库!A:N,8,FALSE) -> 0 | F16: 6 | G16: Mỹ Nhàn 美嫻 | H16: Thùy 阿锤 | I16: Xuân Nhi 春妮 | J16: 11/12/2025 | K16: 0.38680556
A17: =VLOOKUP($C17,SKU!$A:$I,3,FALSE) -> 10062 | B17: =VLOOKUP($C17,SKU!$A:$I,2,FALSE) -> Mobile Legends: Bang Bang-Collectible Cards-Hand of Destiny-001A-SEA | C17: Kayou Mobile Legend | D17: 1 | E17: =D17*VLOOKUP(A17,Nhập入库!A:N,8,FALSE) -> 20 | G17: Bội Anh 倍英 | H17: Uyên Mai 媛梅 | I17: Xuân Nhi 春妮 | J17: 11/12/2025 | K17: 0.52638889
A18: =VLOOKUP($C18,SKU!$A:$I,3,FALSE) -> 10002 | B18: =VLOOKUP($C18,SKU!$A:$I,2,FALSE) -> MoonCard月卡《美少女战士》第三弹 | C18: Moon Card Sailor Moon | D18: 0 | E18: =D18*VLOOKUP(A18,Nhập入库!A:N,8,FALSE) -> 0 | F18: 40 | G18: Thùy 阿锤 | H18: Thanh Vy 清薇 | I18: Tú phượng 苏凤 | J18: 11/12/2025 | K18: 0.625
A19: =VLOOKUP($C19,SKU!$A:$I,3,FALSE) -> 10072 | B19: =VLOOKUP($C19,SKU!$A:$I,2,FALSE) -> 伴飞小鸟 | C19: Mô hình chim đồ chơi trang trí xe | D19: 3 | E19: =D19*VLOOKUP(A19,Nhập入库!A:N,8,FALSE) -> 3 | G19: Thùy 阿锤 | H19: Thành Đạt 成达 | I19: Xuân Nhi 春妮 | J19: 11/12/2025 | K19: 0.58333333
A20: =VLOOKUP($C20,SKU!$A:$I,3,FALSE) -> 10057 | B20: =VLOOKUP($C20,SKU!$A:$I,2,FALSE) -> 三丽鸥家族暖冬 | C20: Kabao Sanrio Gia tộc mùa đông ấm áp | D20: 0 | E20: 0 | F20: 15 | G20: Bội Anh 倍英 | H20: Thùy 阿锤 | I20: Xuân Nhi 春妮 | J20: 11/12/2025 | K20: 0.60416667
A21: =VLOOKUP($C21,SKU!$A:$I,3,FALSE) -> 10060 | B21: =VLOOKUP($C21,SKU!$A:$I,2,FALSE) -> 漫の森《宫崎骏第三弹·奇幻之旅》 | C21: Manga Forest Ghibli vol 3 | D21: 0 | E21: 0 | F21: 10 | G21: Phước 小福 | H21: Thúy Phụng 翠凤 | I21: Xuân Nhi 春妮 | J21: 11/12/2025 | K21: 0.60763889
A22: =VLOOKUP($C22,SKU!$A:$I,3,FALSE) -> 10039 | B22: =VLOOKUP($C22,SKU!$A:$I,2,FALSE) -> 非凡航海王第五弹 | C22: OP Phi Phàm | D22: 2 | E22: 40 | G22: Uyên Mai 媛梅 | H22: Thúy Phụng 翠凤 | I22: Xuân Nhi 春妮 | J22: 11/12/2025 | K22: 0.60972222
A23: =VLOOKUP($C23,SKU!$A:$I,3,FALSE) -> 10075 | B23: =VLOOKUP($C23,SKU!$A:$I,2,FALSE) -> 《万卡卡文创》鬼灭之刃日轮破晓第一弹 | C23: Wanka Thanh gươm diệt quỷ ver Nhật luân | D23: 2 | E23: =D23*VLOOKUP(A23,Nhập入库!A:N,8,FALSE) -> 20 | G23: Thanh Vy 清薇 | H23: Vi 小薇 | I23: Hoàng Oanh黄莹 | J23: 12/12/2025 | K23: 0.92916667
A24: =VLOOKUP($C24,SKU!$A:$I,3,FALSE) -> 10075 | B24: =VLOOKUP($C24,SKU!$A:$I,2,FALSE) -> 《万卡卡文创》鬼灭之刃日轮破晓第一弹 | C24: Wanka Thanh gươm diệt quỷ ver Nhật luân | D24: 3 | E24: =D24*VLOOKUP(A24,Nhập入库!A:N,8,FALSE) -> 30 | G24: Mimi | H24: Vi 小薇 | I24: Hoàng Oanh黄莹 | J24: 12/12/2025 | K24: 0.98263889
A25: =VLOOKUP($C25,SKU!$A:$I,3,FALSE) -> 10008 | B25: =VLOOKUP($C25,SKU!$A:$I,2,FALSE) -> XWork美少女战士-璀璨之梦 | C25: X work Sailor Moon | E25: =D25*VLOOKUP(A25,Nhập入库!A:N,8,FALSE) -> 0 | F25: 36 | G25: Test Live | H25: Mỹ Nhàn 美嫻 | I25: Tum 阿庄 | J25: 11/12/2025 | K25: 0.83333333
